Workbook

Sheet Review món
A2: Cá biển chiên sốt mắm tỏi | B2: 8/10
A3: Gà | B3: 8/10
A4: Mực sữa rim mặn | B4: 3/10 | C4: dở
A5: Com trứng chiên | B5: 10000/10 | C5: quá đỉnh
A6: Bò kho | B6: 6/10 | C6: ít bò quá lâu lâu dai dai

Sheet DEPOSIT
A1: Tên | B1: Nạp vào | C1: Sử dụng | D1: Còn lại | J1: 46192 | K1: 46191 | L1: 46190 | M1: 46189 | N1: 46188 | O1: 46185 | P1: 46184 | Q1: 46183 | R1: 46182 | S1: 46181 | T1: 46178 | U1: 46177 | V1: 46176 | W1: 46175 | X1: 46174 | Y1: 46171 | Z1: 46170 | AA1: 46169 | AB1: 46168 | AC1: 46167 | AD1: 46163 | AE1: 46162 | AF1: 46161 | AG1: 46160 | AH1: 46157 | AI1: 46156 | AJ1: 46155 | AK1: 46154 | AL1: 46153 | AM1: 46150 | AN1: 46149 | AO1: 46148 | AP1: 46147 | AQ1: 46146 | AR1: 46136 | AS1: 46135 | AT1: 46134 | AU1: 46133
A2: Hiếu | B2: =109+135+'11-05-2026'!M20+46+'26-05-2026'!M20+'05-06-2026'!M20+'12-06-2026'!M20+'15-06-2026'!M20 -> 1172 | C2: =SUM(I2:EG2)+64 -> 1075 | D2: =B2-C2 -> 97 | J2: ='19-06-2026'!J2 -> 0 | K2: ='18-06-2026'!J2 -> 27 | L2: ='17-06-2026'!J2 -> 27 | M2: ='16-06-2026'!J2 -> 25 | N2: ='15-06-2026'!J2 -> 26 | O2: ='12-06-2026'!J2 -> 31 | P2: ='11-06-2026'!J2 -> 26 | Q2: ='10-06-2026'!J2 -> 26 | R2: ='09-06-2026'!J2 -> 24 | S2: ='08-06-2026'!J2 -> 28 | T2: ='05-06-2026'!J2 -> 33 | U2: ='04-06-2026'!J2 -> 25 | V2: ='03-06-2026'!J2 -> 25 | W2: ='02-06-2026'!J2 -> 29 | X2: ='01-06-2026'!J2 -> 25 | Y2: ='29-05-2026'!J2 -> 32 | Z2: ='28-05-2026'!J2 -> 27 | AA2: ='27-05-2026'!J2 -> 29 | AB2: ='26-05-2026'!J2 -> 29 | AC2: ='25-05-2026 '!J2 -> 26 | AD2: ='21-05-2026'!J2 -> 26 | AE2: ='20-05-2026'!J2 -> 27 | AF2: ='19-05-2026'!J2 -> 29 | AG2: ='18-05-2026 '!J2 -> 27 | AH2: ='15-05-2026'!J2 -> 29 | AI2: ='14-05-2026'!J2 -> 28 | AJ2: ='13-05-2026'!J2 -> 26 | AK2: ='12-05-2026'!J2 -> 28 | AL2: ='11-05-2026'!J2 -> 27 | AM2: ='08-05-2026'!J2 -> 28 | AN2: ='07-05-2026'!J2 -> 27 | AO2: ='06-05-2026'!J2 -> 26 | AP2: ='05-05-2026'!J2 -> 27 | AQ2: ='04-05-2026'!J2 -> 27 | AR2: ='24-04-2026'!J2 -> 32 | AS2: ='23-04-2026'!J2 -> 26 | AT2: ='22-04-2026'!J2 -> 25 | AU2: ='21-04-2026'!J2 -> 26
A3: Trọng | B3: =136+165+117+262 -> 680 | C3: =SUM(I3:EG3) -> 680 | D3: =B3-C3 -> 0 | J3: ='19-06-2026'!J3 -> 0 | K3: ='18-06-2026'!J3 -> 27 | L3: ='17-06-2026'!J3 -> 27 | M3: ='16-06-2026'!J3 -> 25 | N3: ='15-06-2026'!J3 -> 0 | O3: ='12-06-2026'!J3 -> 0 | P3: ='11-06-2026'!J3 -> 26 | Q3: ='10-06-2026'!J3 -> 26 | R3: ='09-06-2026'!J3 -> 24 | S3: ='08-06-2026'!J3 -> 28 | T3: ='05-06-2026'!J3 -> 0 | U3: ='04-06-2026'!J3 -> 25 | V3: ='03-06-2026'!J3 -> 25 | W3: ='02-06-2026'!J3 -> 29 | X3: ='01-06-2026'!J3 -> 35 | Y3: ='29-05-2026'!J3 -> 0 | Z3: ='28-05-2026'!J3 -> 27 | AA3: ='27-05-2026'!J3 -> 29 | AB3: ='26-05-2026'!J3 -> 0 | AC3: ='25-05-2026 '!J3 -> 0 | AD3: ='21-05-2026'!J3 -> 26 | AE3: ='20-05-2026'!J3 -> 0 | AF3: ='19-05-2026'!J3 -> 0 | AG3: ='18-05-2026 '!J3 -> 27 | AH3: ='15-05-2026'!J3 -> 29 | AI3: ='14-05-2026'!J3 -> 0 | AJ3: ='13-05-2026'!J3 -> 0 | AK3: ='12-05-2026'!J3 -> 28 | AL3: ='11-05-2026'!J3 -> 0 | AM3: ='08-05-2026'!J3 -> 28 | AN3: ='07-05-2026'!J3 -> 27 | AO3: ='06-05-2026'!J3 -> 26 | AP3: ='05-05-2026'!J3 -> 0 | AQ3: ='04-05-2026'!J3 -> 27 | AR3: ='24-04-2026'!J3 -> 32 | AS3: ='23-04-2026'!J3 -> 26 | AT3: ='22-04-2026'!J3 -> 25 | AU3: ='21-04-2026'!J3 -> 26
A4: Kiêm | B4: ='24-04-2026'!M21+20+320+70+226 -> 867 | C4: =SUM(I4:EG4)+30+22+32 -> 867 | D4: =B4-C4 -> 0 | J4: ='19-06-2026'!J4 -> 0 | K4: ='18-06-2026'!J4 -> 0 | L4: ='17-06-2026'!J4 -> 0 | M4: ='16-06-2026'!J4 -> 0 | N4: ='15-06-2026'!J4 -> 0 | O4: ='12-06-2026'!J4 -> 0 | P4: ='11-06-2026'!J4 -> 0 | Q4: ='10-06-2026'!J4 -> 0 | R4: ='09-06-2026'!J4 -> 0 | S4: ='08-06-2026'!J4 -> 0 | T4: ='05-06-2026'!J4 -> 43 | U4: ='04-06-2026'!J4 -> 35 | V4: ='03-06-2026'!J4 -> 25 | W4: ='02-06-2026'!J4 -> 39 | X4: ='01-06-2026'!J4 -> 25 | Y4: ='29-05-2026'!J4 -> 47 | Z4: ='28-05-2026'!J4 -> 27 | AA4: ='27-05-2026'!J4 -> 0 | AB4: ='26-05-2026'!J4 -> 29 | AC4: ='25-05-2026 '!J4 -> 36 | AD4: ='21-05-2026'!J4 -> 0 | AE4: ='20-05-2026'!J4 -> 0 | AF4: ='19-05-2026'!J4 -> 0 | AG4: ='18-05-2026 '!J4 -> 37 | AH4: ='15-05-2026'!J4 -> 39 | AI4: ='14-05-2026'!J4 -> 38 | AJ4: ='13-05-2026'!J4 -> 36 | AK4: ='12-05-2026'!J4 -> 28 | AL4: ='11-05-2026'!J4 -> 37 | AM4: ='08-05-2026'!J4 -> 38 | AN4: ='07-05-2026'!J4 -> 0 | AO4: ='06-05-2026'!J4 -> 26 | AP4: ='05-05-2026'!J4 -> 27 | AQ4: ='04-05-2026'!J4 -> 27 | AR4: ='24-04-2026'!J4 -> 42 | AS4: ='23-04-2026'!J4 -> 26 | AT4: ='22-04-2026'!J4 -> 50 | AU4: ='21-04-2026'!J4 -> 26
A5: Anh Dũng | B5: =500+500+500+500 -> 2000 | C5: =SUM(I5:EG5)+22 -> 1033 | D5: =B5-C5 -> 967 | J5: ='19-06-2026'!J5 -> 0 | K5: ='18-06-2026'!J5 -> 27 | L5: ='17-06-2026'!J5 -> 27 | M5: ='16-06-2026'!J5 -> 25 | N5: ='15-06-2026'!J5 -> 26 | O5: ='12-06-2026'!J5 -> 31 | P5: ='11-06-2026'!J5 -> 26 | Q5: ='10-06-2026'!J5 -> 26 | R5: ='09-06-2026'!J5 -> 24 | S5: ='08-06-2026'!J5 -> 28 | T5: ='05-06-2026'!J5 -> 33 | U5: ='04-06-2026'!J5 -> 25 | V5: ='03-06-2026'!J5 -> 25 | W5: ='02-06-2026'!J5 -> 29 | X5: ='01-06-2026'!J5 -> 25 | Y5: ='29-05-2026'!J5 -> 32 | Z5: ='28-05-2026'!J5 -> 27 | AA5: ='27-05-2026'!J5 -> 29 | AB5: ='26-05-2026'!J5 -> 29 | AC5: ='25-05-2026 '!J5 -> 26 | AD5: ='21-05-2026'!J5 -> 26 | AE5: ='20-05-2026'!J5 -> 27 | AF5: ='19-05-2026'!J5 -> 29 | AG5: ='18-05-2026 '!J5 -> 27 | AH5: ='15-05-2026'!J5 -> 29 | AI5: ='14-05-2026'!J5 -> 28 | AJ5: ='13-05-2026'!J5 -> 26 | AK5: ='12-05-2026'!J5 -> 28 | AL5: ='11-05-2026'!J5 -> 27 | AM5: ='08-05-2026'!J5 -> 28 | AN5: ='07-05-2026'!J5 -> 27 | AO5: ='06-05-2026'!J5 -> 26 | AP5: ='05-05-2026'!J5 -> 27 | AQ5: ='04-05-2026'!J5 -> 27 | AR5: ='24-04-2026'!J5 -> 32 | AS5: ='23-04-2026'!J5 -> 26 | AT5: ='22-04-2026'!J5 -> 25 | AU5: ='21-04-2026'!J5 -> 26
A6: Hoàng Anh | B6: =36+213 -> 249 | C6: =SUM(I6:EG6)+35+22 -> 413 | D6: =B6-C6 -> -164 | J6: ='19-06-2026'!J6 -> 0 | K6: ='18-06-2026'!J6 -> 0 | L6: ='17-06-2026'!J6 -> 27 | M6: ='16-06-2026'!J6 -> 0 | N6: ='15-06-2026'!J6 -> 26 | O6: ='12-06-2026'!J6 -> 0 | P6: ='11-06-2026'!J6 -> 26 | Q6: ='10-06-2026'!J6 -> 0 | R6: ='09-06-2026'!J6 -> 0 | S6: ='08-06-2026'!J6 -> 28 | T6: ='05-06-2026'!J6 -> 0 | U6: ='04-06-2026'!J6 -> 0 | V6: ='03-06-2026'!J6 -> 25 | W6: ='02-06-2026'!J6 -> 0 | X6: ='01-06-2026'!J6 -> 25 | Y6: ='29-05-2026'!J6 -> 0 | Z6: ='28-05-2026'!J6 -> 0 | AA6: ='27-05-2026'!J6 -> 0 | AB6: ='26-05-2026'!J6 -> 0 | AC6: ='25-05-2026 '!J6 -> 0 | AD6: ='21-05-2026'!J6 -> 0 | AE6: ='20-05-2026'!J6 -> 0 | AF6: ='19-05-2026'!J6 -> 0 | AG6: ='18-05-2026 '!J6 -> 0 | AH6: ='15-05-2026'!J6 -> 0 | AI6: ='14-05-2026'!J6 -> 28 | AJ6: ='13-05-2026'!J6 -> 0 | AK6: ='12-05-2026'!J6 -> 0 | AL6: ='11-05-2026'!J6 -> 27 | AM6: ='08-05-2026'!J6 -> 28 | AN6: ='07-05-2026'!J6 -> 27 | AO6: ='06-05-2026'!J6 -> 0 | AP6: ='05-05-2026'!J6 -> 27 | AQ6: ='04-05-2026'!J6 -> 0 | AR6: ='24-04-2026'!J6 -> 0 | AS6: ='23-04-2026'!J6 -> 26 | AT6: ='22-04-2026'!J6 -> 0 | AU6: ='21-04-2026'!J6 -> 36
A7: Lê Thành Công | B7: =164+65+158+220+259 -> 866 | C7: =SUM(I7:EG7) -> 866 | D7: =B7-C7 -> 0 | J7: ='19-06-2026'!J7 -> 0 | K7: ='18-06-2026'!J7 -> 0 | L7: ='17-06-2026'!J7 -> 0 | M7: ='16-06-2026'!J7 -> 0 | N7: ='15-06-2026'!J7 -> 0 | O7: ='12-06-2026'!J7 -> 31 | P7: ='11-06-2026'!J7 -> 26 | Q7: ='10-06-2026'!J7 -> 26 | R7: ='09-06-2026'!J7 -> 24 | S7: ='08-06-2026'!J7 -> 28 | T7: ='05-06-2026'!J7 -> 0 | U7: ='04-06-2026'!J7 -> 35 | V7: ='03-06-2026'!J7 -> 25 | W7: ='02-06-2026'!J7 -> 29 | X7: ='01-06-2026'!J7 -> 35 | Y7: ='29-05-2026'!J7 -> 0 | Z7: ='28-05-2026'!J7 -> 27 | AA7: ='27-05-2026'!J7 -> 29 | AB7: ='26-05-2026'!J7 -> 29 | AC7: ='25-05-2026 '!J7 -> 26 | AD7: ='21-05-2026'!J7 -> 26 | AE7: ='20-05-2026'!J7 -> 27 | AF7: ='19-05-2026'!J7 -> 29 | AG7: ='18-05-2026 '!J7 -> 27 | AH7: ='15-05-2026'!J7 -> 39 | AI7: ='14-05-2026'!J7 -> 28 | AJ7: ='13-05-2026'!J7 -> 36 | AK7: ='12-05-2026'!J7 -> 28 | AL7: ='11-05-2026'!J7 -> 27 | AM7: ='08-05-2026'!J7 -> 38 | AN7: ='07-05-2026'!J7 -> 27 | AO7: ='06-05-2026'!J7 -> 26 | AP7: ='05-05-2026'!J7 -> 27 | AQ7: ='04-05-2026'!J7 -> 27 | AR7: ='24-04-2026'!J7 -> 32 | AS7: ='23-04-2026'!J7 -> 26 | AT7: ='22-04-2026'!J7 -> 0 | AU7: ='21-04-2026'!J7 -> 26
A8: Tùng | B8: =162+192+292 -> 646 | C8: =SUM(I8:EG8)+41 -> 646 | D8: =B8-C8 -> 0 | J8: ='19-06-2026'!J8 -> 0 | K8: ='18-06-2026'!J8 -> 27 | L8: ='17-06-2026'!J8 -> 0 | M8: ='16-06-2026'!J8 -> 0 | N8: ='15-06-2026'!J8 -> 26 | O8: ='12-06-2026'!J8 -> 31 | P8: ='11-06-2026'!J8 -> 26 | Q8: ='10-06-2026'!J8 -> 26 | R8: ='09-06-2026'!J8 -> 0 | S8: ='08-06-2026'!J8 -> 28 | T8: ='05-06-2026'!J8 -> 33 | U8: ='04-06-2026'!J8 -> 25 | V8: ='03-06-2026'!J8 -> 0 | W8: ='02-06-2026'!J8 -> 29 | X8: ='01-06-2026'!J8 -> 25 | Y8: ='29-05-2026'!J8 -> 0 | Z8: ='28-05-2026'!J8 -> 27 | AA8: ='27-05-2026'!J8 -> 0 | AB8: ='26-05-2026'!J8 -> 29 | AC8: ='25-05-2026 '!J8 -> 0 | AD8: ='21-05-2026'!J8 -> 0 | AE8: ='20-05-2026'!J8 -> 27 | AF8: ='19-05-2026'!J8 -> 29 | AG8: ='18-05-2026 '!J8 -> 27 | AH8: ='15-05-2026'!J8 -> 0 | AI8: ='14-05-2026'!J8 -> 0 | AJ8: ='13-05-2026'!J8 -> 0 | AK8: ='12-05-2026'!J8 -> 28 | AL8: ='11-05-2026'!J8 -> 0 | AM8: ='08-05-2026'!J8 -> 0 | AN8: ='07-05-2026'!J8 -> 27 | AO8: ='06-05-2026'!J8 -> 26 | AP8: ='05-05-2026'!J8 -> 0 | AQ8: ='04-05-2026'!J8 -> 0 | AR8: ='24-04-2026'!J8 -> 32 | AS8: ='23-04-2026'!J8 -> 26 | AT8: ='22-04-2026'!J8 -> 25 | AU8: ='21-04-2026'!J8 -> 26
A9: Sỹ | B9: =109+380 -> 489 | C9: =SUM(I9:EG9) -> 949 | D9: =B9-C9 -> -460 | J9: ='19-06-2026'!J9 -> 0 | K9: ='18-06-2026'!J9 -> 27 | L9: ='17-06-2026'!J9 -> 27 | M9: ='16-06-2026'!J9 -> 25 | N9: ='15-06-2026'!J9 -> 26 | O9: ='12-06-2026'!J9 -> 31 | P9: ='11-06-2026'!J9 -> 26 | Q9: ='10-06-2026'!J9 -> 26 | R9: ='09-06-2026'!J9 -> 24 | S9: ='08-06-2026'!J9 -> 28 | T9: ='05-06-2026'!J9 -> 0 | U9: ='04-06-2026'!J9 -> 25 | V9: ='03-06-2026'!J9 -> 25 | W9: ='02-06-2026'!J9 -> 29 | X9: ='01-06-2026'!J9 -> 25 | Y9: ='29-05-2026'!J9 -> 32 | Z9: ='28-05-2026'!J9 -> 27 | AA9: ='27-05-2026'!J9 -> 0 | AB9: ='26-05-2026'!J9 -> 29 | AC9: ='25-05-2026 '!J9 -> 26 | AD9: ='21-05-2026'!J9 -> 26 | AE9: ='20-05-2026'!J9 -> 27 | AF9: ='19-05-2026'!J9 -> 29 | AG9: ='18-05-2026 '!J9 -> 27 | AH9: ='15-05-2026'!J9 -> 29 | AI9: ='14-05-2026'!J9 -> 28 | AJ9: ='13-05-2026'!J9 -> 26 | AK9: ='12-05-2026'!J9 -> 28 | AL9: ='11-05-2026'!J9 -> 27 | AM9: ='08-05-2026'!J9 -> 28 | AN9: ='07-05-2026'!J9 -> 27 | AO9: ='06-05-2026'!J9 -> 26 | AP9: ='05-05-2026'!J9 -> 27 | AQ9: ='04-05-2026'!J9 -> 27 | AR9: ='24-04-2026'!J9 -> 32 | AS9: ='23-04-2026'!J9 -> 26 | AT9: ='22-04-2026'!J9 -> 25 | AU9: ='21-04-2026'!J9 -> 26
A10: Việt | B10: =112+137+185 -> 434 | C10: =SUM(I10:EG10)+47+33 -> 670 | D10: =B10-C10 -> -236 | J10: ='19-06-2026'!J10 -> 0 | K10: ='18-06-2026'!J10 -> 0 | L10: ='17-06-2026'!J10 -> 27 | M10: ='16-06-2026'!J10 -> 25 | N10: ='15-06-2026'!J10 -> 26 | O10: ='12-06-2026'!J10 -> 0 | P10: ='11-06-2026'!J10 -> 26 | Q10: ='10-06-2026'!J10 -> 0 | R10: ='09-06-2026'!J10 -> 24 | S10: ='08-06-2026'!J10 -> 28 | T10: ='05-06-2026'!J10 -> 0 | U10: ='04-06-2026'!J10 -> 25 | V10: ='03-06-2026'!J10 -> 25 | W10: ='02-06-2026'!J10 -> 29 | X10: ='01-06-2026'!J10 -> 0 | Y10: ='29-05-2026'!J10 -> 0 | Z10: ='28-05-2026'!J10 -> 0 | AA10: ='27-05-2026'!J10 -> 0 | AB10: ='26-05-2026'!J10 -> 0 | AC10: ='25-05-2026 '!J10 -> 26 | AD10: ='21-05-2026'!J10 -> 26 | AE10: ='20-05-2026'!J10 -> 27 | AF10: ='19-05-2026'!J10 -> 0 | AG10: ='18-05-2026 '!J10 -> 27 | AH10: ='15-05-2026'!J10 -> 0 | AI10: ='14-05-2026'!J10 -> 28 | AJ10: ='13-05-2026'!J10 -> 0 | AK10: ='12-05-2026'!J10 -> 28 | AL10: ='11-05-2026'!J10 -> 0 | AM10: ='08-05-2026'!J10 -> 28 | AN10: ='07-05-2026'!J10 -> 0 | AO10: ='06-05-2026'!J10 -> 26 | AP10: ='05-05-2026'!J10 -> 27 | AQ10: ='04-05-2026'!J10 -> 27 | AR10: ='24-04-2026'!J10 -> 0 | AS10: ='23-04-2026'!J10 -> 26 | AT10: ='22-04-2026'!J10 -> 33 | AU10: ='21-04-2026'!J10 -> 26
A11: Vinh | B11: =106+28+147+82+27 -> 390 | C11: =SUM(I11:EG11) -> 390 | D11: =B11-C11 -> 0 | J11: ='19-06-2026'!J11 -> 0 | K11: ='18-06-2026'!J11 -> 0 | L11: ='17-06-2026'!J11 -> 27 | M11: ='16-06-2026'!J11 -> 0 | N11: ='15-06-2026'!J11 -> 0 | O11: ='12-06-2026'!J11 -> 0 | P11: ='11-06-2026'!J11 -> 0 | Q11: ='10-06-2026'!J11 -> 0 | R11: ='09-06-2026'!J11 -> 0 | S11: ='08-06-2026'!J11 -> 0 | T11: ='05-06-2026'!J11 -> 0 | U11: ='04-06-2026'!J11 -> 0 | V11: ='03-06-2026'!J11 -> 0 | W11: ='02-06-2026'!J11 -> 0 | X11: ='01-06-2026'!J11 -> 0 | Y11: ='29-05-2026'!J11 -> 0 | Z11: ='28-05-2026'!J11 -> 27 | AA11: ='27-05-2026'!J11 -> 0 | AB11: ='26-05-2026'!J11 -> 29 | AC11: ='25-05-2026 '!J11 -> 26 | AD11: ='21-05-2026'!J11 -> 0 | AE11: ='20-05-2026'!J11 -> 0 | AF11: ='19-05-2026'!J11 -> 0 | AG11: ='18-05-2026 '!J11 -> 27 | AH11: ='15-05-2026'!J11 -> 29 | AI11: ='14-05-2026'!J11 -> 0 | AJ11: ='13-05-2026'!J11 -> 36 | AK11: ='12-05-2026'!J11 -> 28 | AL11: ='11-05-2026'!J11 -> 27 | AM11: ='08-05-2026'!J11 -> 28 | AN11: ='07-05-2026'!J11 -> 0 | AO11: ='06-05-2026'!J11 -> 26 | AP11: ='05-05-2026'!J11 -> 27 | AQ11: ='04-05-2026'!J11 -> 27 | AR11: ='24-04-2026'!J11 -> 0 | AS11: ='23-04-2026'!J11 -> 0 | AT11: ='22-04-2026'!J11 -> 0 | AU11: ='21-04-2026'!J11 -> 26
A12: Hòa | B12: =0 -> 0 | C12: =SUM(I12:EG12) -> 211 | D12: =B12-C12 -> -211 | J12: ='19-06-2026'!J12 -> 0 | K12: ='18-06-2026'!J12 -> 27 | L12: ='17-06-2026'!J12 -> 27 | M12: ='16-06-2026'!J12 -> 25 | N12: ='15-06-2026'!J12 -> 26 | O12: ='12-06-2026'!J12 -> 0 | P12: ='11-06-2026'!J12 -> 0 | Q12: ='10-06-2026'!J12 -> 0 | R12: ='09-06-2026'!J12 -> 24 | S12: ='08-06-2026'!J12 -> 28 | T12: ='05-06-2026'!J12 -> 0 | U12: ='04-06-2026'!J12 -> 0 | V12: ='03-06-2026'!J12 -> 0 | W12: ='02-06-2026'!J12 -> 29 | X12: ='01-06-2026'!J12 -> 25
B17: =SUM(B2:B11) -> 7793 | C17: =SUM(C2:C11) -> 7589 | D17: =SUM(D2:D11) -> 204 | J17: =SUM(J2:J11) -> 0 | K17: =SUM(K2:K11) -> 135 | L17: =SUM(L2:L11) -> 189 | M17: =SUM(M2:M11) -> 125 | N17: =SUM(N2:N11) -> 156 | O17: =SUM(O2:O11) -> 155 | P17: =SUM(P2:P11) -> 208 | Q17: =SUM(Q2:Q11) -> 156 | ... AU17: =SUM(AU2:AU11) -> 270
AU23: =22*70 -> 1540
AU24: =27*22 -> 594
AU25: =AU23-AU24 -> 946
U27: .

Sheet 08-06-2026 (2)
A1: STT | B1: Tên | C1: Tên món | D1: Tên món chay | F1: Note | G1: Link menu | H1: LINK MENU CHAY | I1: Món thêm | J1: Tổng
A2: {=_xlfn.SEQUENCE(15)} -> 1 | B2: Hiếu | E2: FALSE | G2: =IF(C2<>"", M8, 0) -> 0 | J2: =SUM(G2:I2) -> 0
A3: 2 | B3: Trọng | E3: FALSE | G3: =IF(C3<>"", M8, 0) -> 0 | J3: =SUM(G3:I3) -> 0
A4: 3 | B4: Kiêm | E4: FALSE | G4: =IF(C4<>"", M8, 0) -> 0 | I4: 10 | J4: =SUM(G4:I4) -> 10
A5: 4 | B5: Anh Dũng | E5: FALSE | G5: =IF(C5<>"", M8, 0) -> 0 | J5: =SUM(G5:I5) -> 0 | L5: Tổng hợp
A6: 5 | B6: Hoàng Anh | E6: FALSE | G6: =IF(C6<>"", M8, 0) -> 0 | J6: =SUM(G6:I6) -> 0 | L6: Số người ăn | M6: =COUNTA(C2:C16) -> 0
A7: 6 | B7: Lê Thành Công | E7: FALSE | G7: =IF(C7<>"", M8, 0) -> 0 | J7: =SUM(G7:I7) -> 0 | L7: Tổng tiền | M7: =M19+M20-10 -> 133
A8: 7 | B8: Tùng | E8: FALSE | G8: =IF(C8<>"", M8, 0) -> 0 | J8: =SUM(G8:I8) -> 0 | L8: Mỗi người | M8: =ROUND(M7/M6,0) -> #DIV/0!
A9: 8 | B9: Sỹ | E9: FALSE | G9: =IF(C9<>"", M8, 0) -> 0 | J9: =SUM(G9:I9) -> 0
A10: 9 | B10: Việt | E10: FALSE | G10: =IF(C10<>"", M8, 0) -> 0 | J10: =SUM(G10:I10) -> 0
A11: 10 | B11: Vinh | E11: FALSE | G11: =IF(C11<>"", M8, 0) -> 0 | J11: =SUM(G11:I11) -> 0 | L11: Tổng hợp chay
A12: 11 | B12: Hòa | E12: FALSE | G12: =IF(C12<>"", M8, 0) -> 0 | J12: =SUM(G12:I12) -> 0 | L12: Số người ăn | M12: =COUNTA(D2:D16) -> 0
A13: 12 | B13: Hieuthuhai | E13: FALSE | L13: Tổng tiền
A14: 13 | E14: FALSE | L14: Mỗi người | M14: =ROUNDUP(M13/M12,0) -> #DIV/0!
A15: 14 | E15: FALSE
A16: 15 | E16: FALSE
A17: Đã đặt
G18: =SUM(G2:G16) -> 0 | J18: =SUM(J2:J16) -> 10
E19: =COUNTIF(E2:E16,TRUE) -> 0 | L19: Trọng
L20: Hiếu | M20: 143
L21: Kiêm
L23: =SUM(M20:M22) -> 143

Sheet 19-06-2026
A1: STT | B1: Tên | C1: Tên món | D1: Tên món chay | F1: Note | G1: Menu | H1: LINK MENU CHAY | I1: Món thêm | J1: Tổng
A2: {=_xlfn.SEQUENCE(15)} -> 1 | B2: Hiếu | E2: FALSE | G2: =IF(C2<>"", M8, 0) -> 0 | J2: =SUM(G2:I2) -> 0
A3: 2 | B3: Trọng | E3: FALSE | G3: =IF(C3<>"", M8, 0) -> 0 | J3: =SUM(G3:I3) -> 0
A4: 3 | B4: Kiêm | E4: FALSE | G4: =IF(C4<>"", M8, 0) -> 0 | J4: =SUM(G4:I4) -> 0
A5: 4 | B5: Anh Dũng | E5: FALSE | G5: =IF(C5<>"", M8, 0) -> 0 | J5: =SUM(G5:I5) -> 0 | L5: Tổng hợp
A6: 5 | B6: Hoàng Anh | E6: FALSE | G6: =IF(C6<>"", M8, 0) -> 0 | J6: =SUM(G6:I6) -> 0 | L6: Số người ăn | M6: =COUNTA(C2:C16) -> 0
A7: 6 | B7: Lê Thành Công | E7: FALSE | G7: =IF(C7<>"", M9, 0) -> 0 | J7: =SUM(G7:I7) -> 0 | L7: Tổng tiền | M7: =M19+M20 -> 0
A8: 7 | B8: Tùng | E8: FALSE | G8: =IF(C7<>"", M8, 0) -> 0 | J8: =SUM(G8:I8) -> 0 | L8: Mỗi người | M8: =ROUND(M7/M6,0) -> #DIV/0!
A9: 8 | B9: Sỹ | E9: FALSE | G9: =IF(C9<>"", M8, 0) -> 0 | J9: =SUM(G9:I9) -> 0
A10: 9 | B10: Việt | E10: FALSE | G10: =IF(C10<>"", M8, 0) -> 0 | J10: =SUM(G10:I10) -> 0
A11: 10 | B11: Vinh | E11: FALSE | G11: =IF(C11<>"", M8, 0) -> 0 | J11: =SUM(G11:I11) -> 0 | L11: Tổng hợp chay
A12: 11 | B12: Hòa | E12: FALSE | G12: =IF(C12<>"", M8, 0) -> 0 | J12: =SUM(G12:I12) -> 0 | L12: Số người ăn | M12: =COUNTA(D2:D16) -> 0
A13: 12 | B13: Hieuthuhai | E13: FALSE | L13: Tổng tiền
A14: 13 | E14: FALSE | L14: Mỗi người | M14: =ROUNDUP(M13/M12,0) -> #DIV/0!
A15: 14 | E15: FALSE
A16: 15 | E16: FALSE
G18: =SUM(G2:G16) -> 0 | J18: =SUM(J2:J16) -> 0
E19: =COUNTIF(E2:E16,TRUE) -> 0 | L19: Trọng
L20: Hiếu
L21: Kiêm
L23: =SUM(M20:M22) -> 0

Sheet 18-06-2026
A1: STT | B1: Tên | C1: Tên món | D1: Tên món chay | F1: Note | G1: Menu | H1: LINK MENU CHAY | I1: Món thêm | J1: Tổng
A2: {=_xlfn.SEQUENCE(15)} -> 1 | B2: Hiếu | C2: thịt luộc | E2: TRUE | G2: =IF(C2<>"", M8, 0) -> 27 | J2: =SUM(G2:I2) -> 27
A3: 2 | B3: Trọng | C3: đùi gà chiên nước mắm | E3: TRUE | G3: =IF(C3<>"", M8, 0) -> 27 | J3: =SUM(G3:I3) -> 27
A4: 3 | B4: Kiêm | E4: FALSE | G4: =IF(C4<>"", M8, 0) -> 0 | J4: =SUM(G4:I4) -> 0
A5: 4 | B5: Anh Dũng | C5: cá | E5: TRUE | G5: =IF(C5<>"", M8, 0) -> 27 | J5: =SUM(G5:I5) -> 27 | L5: Tổng hợp
A6: 5 | B6: Hoàng Anh | E6: FALSE | G6: =IF(C6<>"", M8, 0) -> 0 | J6: =SUM(G6:I6) -> 0 | L6: Số người ăn | M6: =COUNTA(C2:C16) -> 7
A7: 6 | B7: Lê Thành Công | C7: cơm gà phile | E7: TRUE | G7: =IF(C7<>"", M9, 0) -> 0 | J7: =SUM(G7:I7) -> 0 | L7: Tổng tiền | M7: =M19+M20 -> 191
A8: 7 | B8: Tùng | C8: gà phile | E8: TRUE | G8: =IF(C7<>"", M8, 0) -> 27 | J8: =SUM(G8:I8) -> 27 | L8: Mỗi người | M8: =ROUND(M7/M6,0) -> 27
A9: 8 | B9: Sỹ | C9: Thịt xào măng cay | E9: TRUE | G9: =IF(C9<>"", M8, 0) -> 27 | J9: =SUM(G9:I9) -> 27
A10: 9 | B10: Việt | E10: FALSE | F10: rau thêm, mua chứ hok xin pls/ ai bán mà m mua? | G10: =IF(C10<>"", M8, 0) -> 0 | J10: =SUM(G10:I10) -> 0
A11: 10 | B11: Vinh | E11: FALSE | G11: =IF(C11<>"", M8, 0) -> 0 | J11: =SUM(G11:I11) -> 0 | L11: Tổng hợp chay
A12: 11 | B12: Hòa | C12: thịt xào măng | E12: TRUE | G12: =IF(C12<>"", M8, 0) -> 27 | J12: =SUM(G12:I12) -> 27 | L12: Số người ăn | M12: =COUNTA(D2:D16) -> 0
A13: 12 | B13: Hieuthuhai | E13: FALSE | L13: Tổng tiền
A14: 13 | E14: FALSE | L14: Mỗi người | M14: =ROUNDUP(M13/M12,0) -> #DIV/0!
A15: 14 | E15: FALSE
A16: 15 | E16: FALSE
G18: =SUM(G2:G16) -> 162 | J18: =SUM(J2:J16) -> 162
E19: =COUNTIF(E2:E16,TRUE) -> 7 | L19: Trọng | M19: 191
L20: Hiếu
L21: Kiêm
L23: =SUM(M20:M22) -> 0

Sheet 17-06-2026
A1: STT | B1: Tên | C1: Tên món | D1: Tên món chay | F1: Note | G1: êc | H1: LINK MENU CHAY | I1: Món thêm | J1: Tổng
A2: {=_xlfn.SEQUENCE(15)} -> 1 | B2: Hiếu | C2: ếch xào xả ớt | E2: TRUE | G2: =IF(C2<>"", M8, 0) -> 27 | J2: =SUM(G2:I2) -> 27
A3: 2 | B3: Trọng | C3: cơm thịt xào đậu cove + nấm | E3: TRUE | G3: =IF(C3<>"", M8, 0) -> 27 | J3: =SUM(G3:I3) -> 27
A4: 3 | B4: Kiêm | E4: FALSE | G4: =IF(C4<>"", M8, 0) -> 0 | J4: =SUM(G4:I4) -> 0
A5: 4 | B5: Anh Dũng | C5: cá | E5: TRUE | G5: =IF(C5<>"", M8, 0) -> 27 | J5: =SUM(G5:I5) -> 27 | L5: Tổng hợp
A6: 5 | B6: Hoàng Anh | C6: đùi gà chiên nước múm | E6: TRUE | F6: rau thêm <3 | G6: =IF(C6<>"", M8, 0) -> 27 | J6: =SUM(G6:I6) -> 27 | L6: Số người ăn | M6: =COUNTA(C2:C16) -> 9
A7: 6 | B7: Lê Thành Công | E7: FALSE | G7: =IF(C7<>"", M9, 0) -> 0 | J7: =SUM(G7:I7) -> 0 | L7: Tổng tiền | M7: =M19+M20 -> 239
A8: 7 | B8: Tùng | C8: gà Free lê | E8: TRUE | G8: =IF(C7<>"", M8, 0) -> 0 | J8: =SUM(G8:I8) -> 0 | L8: Mỗi người | M8: =ROUND(M7/M6,0) -> 27
A9: 8 | B9: Sỹ | C9: Bò kho | E9: TRUE | G9: =IF(C9<>"", M8, 0) -> 27 | J9: =SUM(G9:I9) -> 27
A10: 9 | B10: Việt | C10: đùi gà chiên nước múm | E10: TRUE | F10: rau thêm <3 | G10: =IF(C10<>"", M8, 0) -> 27 | J10: =SUM(G10:I10) -> 27
A11: 10 | B11: Vinh | C11: cơm thịt kho tôm | E11: TRUE | G11: =IF(C11<>"", M8, 0) -> 27 | J11: =SUM(G11:I11) -> 27 | L11: Tổng hợp chay
A12: 11 | B12: Hòa | C12: thịt xào măng | E12: TRUE | G12: =IF(C12<>"", M8, 0) -> 27 | J12: =SUM(G12:I12) -> 27 | L12: Số người ăn | M12: =COUNTA(D2:D16) -> 0
A13: 12 | B13: Hieuthuhai | E13: FALSE | L13: Tổng tiền
A14: 13 | E14: FALSE | L14: Mỗi người | M14: =ROUNDUP(M13/M12,0) -> #DIV/0!
A15: 14 | E15: FALSE
A16: 15 | E16: FALSE
A17: ĐÃ ĐẶT
G18: =SUM(G2:G16) -> 216 | J18: =SUM(J2:J16) -> 216
E19: =COUNTIF(E2:E16,TRUE) -> 9 | L19: Trọng | M19: 239
L20: Hiếu
L21: Kiêm
L23: =SUM(M20:M22) -> 0

Sheet 16-06-2026
A1: STT | B1: Tên | C1: Tên món | D1: Tên món chay | F1: Note | G1: Link menu | H1: LINK MENU CHAY | I1: Món thêm | J1: Tổng
A2: {=_xlfn.SEQUENCE(15)} -> 1 | B2: Hiếu | C2: Cơm thị nướng | E2: TRUE | G2: =IF(C2<>"", M8, 0) -> 25 | J2: =SUM(G2:I2) -> 25
A3: 2 | B3: Trọng | C3: Cơm thị nướng | E3: TRUE | G3: =IF(C3<>"", M8, 0) -> 25 | J3: =SUM(G3:I3) -> 25
A4: 3 | B4: Kiêm | E4: FALSE | G4: =IF(C4<>"", M8, 0) -> 0 | J4: =SUM(G4:I4) -> 0
A5: 4 | B5: Anh Dũng | C5: cá | E5: TRUE | G5: =IF(C5<>"", M8, 0) -> 25 | J5: =SUM(G5:I5) -> 25 | L5: Tổng hợp
A6: 5 | B6: Hoàng Anh | E6: FALSE | G6: =IF(C6<>"", M8, 0) -> 0 | J6: =SUM(G6:I6) -> 0 | L6: Số người ăn | M6: =COUNTA(C2:C16) -> 7
A7: 6 | B7: Lê Thành Công | E7: FALSE | G7: =IF(C7<>"", M9, 0) -> 0 | J7: =SUM(G7:I7) -> 0 | L7: Tổng tiền | M7: =M19+M20 -> 173
A8: 7 | B8: Tùng | C8: gà phile | E8: TRUE | G8: =IF(C7<>"", M8, 0) -> 0 | J8: =SUM(G8:I8) -> 0 | L8: Mỗi người | M8: =ROUND(M7/M6,0) -> 25
A9: 8 | B9: Sỹ | C9: Thịt kho trứng | E9: TRUE | F9: Cơm thêm | G9: =IF(C9<>"", M8, 0) -> 25 | J9: =SUM(G9:I9) -> 25
A10: 9 | B10: Việt | C10: Cơm thịt nướng | E10: TRUE | F10: rau thêm | G10: =IF(C10<>"", M8, 0) -> 25 | J10: =SUM(G10:I10) -> 25
A11: 10 | B11: Vinh | E11: FALSE | G11: =IF(C11<>"", M8, 0) -> 0 | J11: =SUM(G11:I11) -> 0 | L11: Tổng hợp chay
A12: 11 | B12: Hòa | C12: Cơm thịt xào măng cay | E12: TRUE | G12: =IF(C12<>"", M8, 0) -> 25 | J12: =SUM(G12:I12) -> 25 | L12: Số người ăn | M12: =COUNTA(D2:D16) -> 0
A13: 12 | B13: Hieuthuhai | E13: FALSE | L13: Tổng tiền
A14: 13 | E14: FALSE | L14: Mỗi người | M14: =ROUNDUP(M13/M12,0) -> #DIV/0!
A15: 14 | E15: FALSE
A16: 15 | E16: FALSE
A17: ĐÃ ĐẶT
G18: =SUM(G2:G16) -> 150 | J18: =SUM(J2:J16) -> 150
E19: =COUNTIF(E2:E16,TRUE) -> 7 | L19: Trọng | M19: 173
L20: Hiếu
L21: Kiêm
L23: =SUM(M20:M22) -> 0

Sheet 15-06-2026
A1: STT | B1: Tên | C1: Tên món | D1: Tên món chay | F1: Note | G1: Link menu | H1: LINK MENU CHAY | I1: Món thêm | J1: Tổng
A2: {=_xlfn.SEQUENCE(15)} -> 1 | B2: Hiếu | C2: gà phi lê | E2: FALSE | G2: =IF(C2<>"", M8, 0) -> 26 | J2: =SUM(G2:I2) -> 26
A3: 2 | B3: Trọng | E3: FALSE | G3: =IF(C3<>"", M8, 0) -> 0 | J3: =SUM(G3:I3) -> 0
A4: 3 | B4: Kiêm | E4: FALSE | G4: =IF(C4<>"", M8, 0) -> 0 | J4: =SUM(G4:I4) -> 0
A5: 4 | B5: Anh Dũng | C5: Cá | E5: FALSE | G5: =IF(C5<>"", M8, 0) -> 26 | J5: =SUM(G5:I5) -> 26 | L5: Tổng hợp
A6: 5 | B6: Hoàng Anh | C6: gà phile | E6: FALSE | G6: =IF(C6<>"", M8, 0) -> 26 | J6: =SUM(G6:I6) -> 26 | L6: Số người ăn | M6: =COUNTA(C2:C16) -> 7
A7: 6 | B7: Lê Thành Công | C7: cơm thịt xào măng cay | E7: FALSE | G7: =IF(C7<>"", M9, 0) -> 0 | J7: =SUM(G7:I7) -> 0 | L7: Tổng tiền | M7: =M19+M20 -> 185
A8: 7 | B8: Tùng | E8: FALSE | G8: =IF(C7<>"", M8, 0) -> 26 | J8: =SUM(G8:I8) -> 26 | L8: Mỗi người | M8: =ROUND(M7/M6,0) -> 26
A9: 8 | B9: Sỹ | C9: Éch xào xả ớt | E9: FALSE | F9: Cơm thêm | G9: =IF(C9<>"", M8, 0) -> 26 | J9: =SUM(G9:I9) -> 26
A10: 9 | B10: Việt | C10: Gà chiên nước mấm | E10: FALSE | G10: =IF(C10<>"", M8, 0) -> 26 | J10: =SUM(G10:I10) -> 26
A11: 10 | B11: Vinh | E11: FALSE | G11: =IF(C11<>"", M8, 0) -> 0 | J11: =SUM(G11:I11) -> 0 | L11: Tổng hợp chay
A12: 11 | B12: Hòa | C12: cơm thịt xào măng cay | E12: FALSE | G12: =IF(C12<>"", M8, 0) -> 26 | J12: =SUM(G12:I12) -> 26 | L12: Số người ăn | M12: =COUNTA(D2:D16) -> 0
A13: 12 | B13: Hieuthuhai | E13: FALSE | L13: Tổng tiền
A14: 13 | E14: FALSE | L14: Mỗi người | M14: =ROUNDUP(M13/M12,0) -> #DIV/0!
A15: 14 | E15: FALSE
A16: 15 | E16: FALSE
G18: =SUM(G2:G16) -> 182 | J18: =SUM(J2:J16) -> 182
E19: =COUNTIF(E2:E16,TRUE) -> 0 | L19: Trọng
L20: Hiếu | M20: 185
L21: Kiêm
L23: =SUM(M20:M22) -> 185

Sheet 12-06-2026
A1: STT | B1: Tên | C1: Tên món | D1: Tên món chay | F1: Note | G1: Link menu | H1: LINK MENU CHAY | I1: Món thêm | J1: Tổng
A2: {=_xlfn.SEQUENCE(15)} -> 1 | B2: Hiếu | C2: Thịt luộc | E2: FALSE | G2: =IF(C2<>"", M8, 0) -> 31 | J2: =SUM(G2:I2) -> 31
A3: 2 | B3: Trọng | E3: FALSE | G3: =IF(C3<>"", M8, 0) -> 0 | J3: =SUM(G3:I3) -> 0
A4: 3 | B4: Kiêm | E4: FALSE | G4: =IF(C4<>"", M8, 0) -> 0 | J4: =SUM(G4:I4) -> 0
A5: 4 | B5: Anh Dũng | C5: Cá | E5: FALSE | G5: =IF(C5<>"", M8, 0) -> 31 | J5: =SUM(G5:I5) -> 31 | L5: Tổng hợp
A6: 5 | B6: Hoàng Anh | E6: FALSE | G6: =IF(C6<>"", M8, 0) -> 0 | J6: =SUM(G6:I6) -> 0 | L6: Số người ăn | M6: =COUNTA(C2:C16) -> 5
A7: 6 | B7: Lê Thành Công | C7: gà phile | E7: FALSE | G7: =IF(C7<>"", M8, 0) -> 31 | J7: =SUM(G7:I7) -> 31 | L7: Tổng tiền | M7: =M19+M20 -> 153
A8: 7 | B8: Tùng | C8: gà phile | E8: FALSE | G8: =IF(C8<>"", M8, 0) -> 31 | J8: =SUM(G8:I8) -> 31 | L8: Mỗi người | M8: =ROUND(M7/M6,0) -> 31
A9: 8 | B9: Sỹ | C9: Lươn again | E9: FALSE | G9: =IF(C9<>"", M8, 0) -> 31 | J9: =SUM(G9:I9) -> 31
A10: 9 | B10: Việt | E10: FALSE | G10: =IF(C10<>"", M8, 0) -> 0 | J10: =SUM(G10:I10) -> 0
A11: 10 | B11: Vinh | E11: FALSE | G11: =IF(C11<>"", M8, 0) -> 0 | J11: =SUM(G11:I11) -> 0 | L11: Tổng hợp chay
A12: 11 | B12: Hòa | E12: FALSE | G12: =IF(C12<>"", M8, 0) -> 0 | J12: =SUM(G12:I12) -> 0 | L12: Số người ăn | M12: =COUNTA(D2:D16) -> 0
A13: 12 | B13: Hieuthuhai | E13: FALSE | L13: Tổng tiền
A14: 13 | E14: FALSE | L14: Mỗi người | M14: =ROUNDUP(M13/M12,0) -> #DIV/0!
A15: 14 | E15: FALSE
A16: 15 | E16: FALSE
G18: =SUM(G2:G16) -> 155 | J18: =SUM(J2:J16) -> 155
E19: =COUNTIF(E2:E16,TRUE) -> 0 | L19: Trọng
L20: Hiếu | M20: 153
L21: Kiêm
L23: =SUM(M20:M22) -> 153

Sheet 11-06-2026
A1: STT | B1: Tên | C1: Tên món | D1: Tên món chay | F1: Note | G1: Link menu | H1: LINK MENU CHAY | I1: Món thêm | J1: Tổng
A2: {=_xlfn.SEQUENCE(15)} -> 1 | B2: Hiếu | C2: cơm gà phi lê | E2: TRUE | G2: =IF(C2<>"", M8, 0) -> 26 | J2: =SUM(G2:I2) -> 26
A3: 2 | B3: Trọng | C3: cơm gà phi lê | E3: TRUE | G3: =IF(C3<>"", M8, 0) -> 26 | J3: =SUM(G3:I3) -> 26
A4: 3 | B4: Kiêm | E4: FALSE | G4: =IF(C4<>"", M8, 0) -> 0 | J4: =SUM(G4:I4) -> 0
A5: 4 | B5: Anh Dũng | C5: cá | E5: TRUE | G5: =IF(C5<>"", M8, 0) -> 26 | J5: =SUM(G5:I5) -> 26 | L5: Tổng hợp
A6: 5 | B6: Hoàng Anh | C6: cơm gà phi lê | E6: TRUE | G6: =IF(C6<>"", M8, 0) -> 26 | J6: =SUM(G6:I6) -> 26 | L6: Số người ăn | M6: =COUNTA(C2:C16) -> 8
A7: 6 | B7: Lê Thành Công | C7: cơm gà phi lê | E7: TRUE | G7: =IF(C7<>"", M8, 0) -> 26 | J7: =SUM(G7:I7) -> 26 | L7: Tổng tiền | M7: =M19+M20 -> 204
A8: 7 | B8: Tùng | C8: cơm gà phi lê | E8: TRUE | G8: =IF(C8<>"", M8, 0) -> 26 | J8: =SUM(G8:I8) -> 26 | L8: Mỗi người | M8: =ROUND(M7/M6,0) -> 26
A9: 8 | B9: Sỹ | C9: Lươn kho sả ớt | E9: TRUE | G9: =IF(C9<>"", M8, 0) -> 26 | J9: =SUM(G9:I9) -> 26
A10: 9 | B10: Việt | C10: Cóm gà chiên nước mắm | E10: TRUE | G10: =IF(C10<>"", M8, 0) -> 26 | J10: =SUM(G10:I10) -> 26
A11: 10 | B11: Vinh | E11: FALSE | G11: =IF(C11<>"", M8, 0) -> 0 | J11: =SUM(G11:I11) -> 0 | L11: Tổng hợp chay
A12: 11 | B12: Hòa | E12: FALSE | G12: =IF(C12<>"", M8, 0) -> 0 | J12: =SUM(G12:I12) -> 0 | L12: Số người ăn | M12: =COUNTA(D2:D16) -> 0
A13: 12 | B13: Hieuthuhai | E13: FALSE | L13: Tổng tiền
A14: 13 | E14: FALSE | L14: Mỗi người | M14: =ROUNDUP(M13/M12,0) -> #DIV/0!
A15: 14 | E15: FALSE
A16: 15 | E16: FALSE
G18: =SUM(G2:G16) -> 208 | J18: =SUM(J2:J16) -> 208
E19: =COUNTIF(E2:E16,TRUE) -> 8 | L19: Trọng | M19: 204
L20: Hiếu
L21: Kiêm
L23: =SUM(M20:M22) -> 0

Sheet 10-06-2026
A1: STT | B1: Tên | C1: Tên món | D1: Tên món chay | F1: Note | G1: Link menu | H1: LINK MENU CHAY | I1: Món thêm | J1: Tổng
A2: {=_xlfn.SEQUENCE(15)} -> 1 | B2: Hiếu | C2: thịt kho đậu | E2: TRUE | G2: =IF(C2<>"", M8, 0) -> 26 | J2: =SUM(G2:I2) -> 26
A3: 2 | B3: Trọng | C3: cá | E3: TRUE | G3: =IF(C3<>"", M8, 0) -> 26 | J3: =SUM(G3:I3) -> 26
A4: 3 | B4: Kiêm | E4: FALSE | G4: =IF(C4<>"", M8, 0) -> 0 | J4: =SUM(G4:I4) -> 0
A5: 4 | B5: Anh Dũng | C5: Cá | E5: TRUE | G5: =IF(C5<>"", M8, 0) -> 26 | J5: =SUM(G5:I5) -> 26 | L5: Tổng hợp
A6: 5 | B6: Hoàng Anh | E6: FALSE | G6: =IF(C6<>"", M8, 0) -> 0 | J6: =SUM(G6:I6) -> 0 | L6: Số người ăn | M6: =COUNTA(C2:C16) -> 6
A7: 6 | B7: Lê Thành Công | C7: cơm trứng chiên | E7: TRUE | G7: =IF(C7<>"", M8, 0) -> 26 | J7: =SUM(G7:I7) -> 26 | L7: Tổng tiền | M7: =M19+M20 -> 158
A8: 7 | B8: Tùng | C8: gà fillet | E8: TRUE | G8: =IF(C8<>"", M8, 0) -> 26 | J8: =SUM(G8:I8) -> 26 | L8: Mỗi người | M8: =ROUND(M7/M6,0) -> 26
A9: 8 | B9: Sỹ | C9: Thịt kho trứng | E9: TRUE | G9: =IF(C9<>"", M8, 0) -> 26 | J9: =SUM(G9:I9) -> 26
A10: 9 | B10: Việt | E10: FALSE | G10: =IF(C10<>"", M8, 0) -> 0 | J10: =SUM(G10:I10) -> 0
A11: 10 | B11: Vinh | E11: FALSE | G11: =IF(C11<>"", M8, 0) -> 0 | J11: =SUM(G11:I11) -> 0 | L11: Tổng hợp chay
A12: 11 | B12: Hòa | E12: FALSE | G12: =IF(C12<>"", M8, 0) -> 0 | J12: =SUM(G12:I12) -> 0 | L12: Số người ăn | M12: =COUNTA(D2:D16) -> 0
A13: 12 | B13: Hieuthuhai | E13: FALSE | L13: Tổng tiền
A14: 13 | E14: FALSE | L14: Mỗi người | M14: =ROUNDUP(M13/M12,0) -> #DIV/0!
A15: 14 | E15: FALSE
A16: 15 | E16: FALSE
G18: =SUM(G2:G16) -> 156 | J18: =SUM(J2:J16) -> 156
E19: =COUNTIF(E2:E16,TRUE) -> 6 | L19: Trọng | M19: 158
L20: Hiếu
L21: Kiêm
L23: =SUM(M20:M22) -> 0

Sheet 09-06-2026
A1: STT | B1: Tên | C1: Tên món | D1: Tên món chay | F1: Note | G1: Link menu | H1: LINK MENU CHAY | I1: Món thêm | J1: Tổng
A2: {=_xlfn.SEQUENCE(15)} -> 1 | B2: Hiếu | C2: trứng chiên | E2: TRUE | G2: =IF(C2<>"", M8, 0) -> 24 | J2: =SUM(G2:I2) -> 24
A3: 2 | B3: Trọng | C3: Mực sữa rim mặn | E3: TRUE | G3: =IF(C3<>"", M8, 0) -> 24 | J3: =SUM(G3:I3) -> 24
A4: 3 | B4: Kiêm | E4: FALSE | G4: =IF(C4<>"", M8, 0) -> 0 | J4: =SUM(G4:I4) -> 0
A5: 4 | B5: Anh Dũng | C5: cá | E5: TRUE | G5: =IF(C5<>"", M8, 0) -> 24 | J5: =SUM(G5:I5) -> 24 | L5: Tổng hợp
A6: 5 | B6: Hoàng Anh | E6: FALSE | G6: =IF(C6<>"", M8, 0) -> 0 | J6: =SUM(G6:I6) -> 0 | L6: Số người ăn | M6: =COUNTA(C2:C16) -> 7
A7: 6 | B7: Lê Thành Công | C7: mực sữa xào hành | E7: TRUE | G7: =IF(C7<>"", M8, 0) -> 24 | J7: =SUM(G7:I7) -> 24 | L7: Tổng tiền | M7: =M19+M20 -> 167
A8: 7 | B8: Tùng | E8: FALSE | G8: =IF(C8<>"", M8, 0) -> 0 | J8: =SUM(G8:I8) -> 0 | L8: Mỗi người | M8: =ROUND(M7/M6,0) -> 24
A9: 8 | B9: Sỹ | C9: Mực sữa rim mặn | E9: TRUE | G9: =IF(C9<>"", M8, 0) -> 24 | J9: =SUM(G9:I9) -> 24
A10: 9 | B10: Việt | C10: Cơm gà chiên nước múm | E10: TRUE | G10: =IF(C10<>"", M8, 0) -> 24 | J10: =SUM(G10:I10) -> 24
A11: 10 | B11: Vinh | E11: FALSE | G11: =IF(C11<>"", M8, 0) -> 0 | J11: =SUM(G11:I11) -> 0 | L11: Tổng hợp chay
A12: 11 | B12: Hòa | C12: mực sữa xào hành | E12: TRUE | G12: =IF(C12<>"", M8, 0) -> 24 | J12: =SUM(G12:I12) -> 24 | L12: Số người ăn | M12: =COUNTA(D2:D16) -> 0
A13: 12 | B13: Hieuthuhai | E13: FALSE | L13: Tổng tiền
A14: 13 | E14: FALSE | L14: Mỗi người | M14: =ROUNDUP(M13/M12,0) -> #DIV/0!
A15: 14 | E15: FALSE
A16: 15 | E16: FALSE
A17: ĐÃ ĐẶT
G18: =SUM(G2:G16) -> 168 | J18: =SUM(J2:J16) -> 168
E19: =COUNTIF(E2:E16,TRUE) -> 7 | L19: Trọng | M19: 167
L20: Hiếu
L21: Kiêm
L23: =SUM(M20:M22) -> 0

Sheet 08-06-2026
A1: STT | B1: Tên | C1: Tên món | D1: Tên món chay | F1: Note | G1: Link menu | H1: LINK MENU CHAY | I1: Món thêm | J1: Tổng
A2: {=_xlfn.SEQUENCE(15)} -> 1 | B2: Hiếu | C2: Gà phi lê | E2: TRUE | G2: =IF(C2<>"", M8, 0) -> 28 | J2: =SUM(G2:I2) -> 28
A3: 2 | B3: Trọng | C3: Gà phi lê | E3: TRUE | G3: =IF(C3<>"", M8, 0) -> 28 | J3: =SUM(G3:I3) -> 28
A4: 3 | B4: Kiêm | E4: FALSE | G4: =IF(C4<>"", M8, 0) -> 0 | J4: =SUM(G4:I4) -> 0
A5: 4 | B5: Anh Dũng | C5: Cá ngừ kho tiêu | E5: TRUE | G5: =IF(C5<>"", M8, 0) -> 28 | J5: =SUM(G5:I5) -> 28 | L5: Tổng hợp
A6: 5 | B6: Hoàng Anh | C6: Gà phi lê | E6: TRUE | G6: =IF(C6<>"", M8, 0) -> 28 | J6: =SUM(G6:I6) -> 28 | L6: Số người ăn | M6: =COUNTA(C2:C16) -> 9
A7: 6 | B7: Lê Thành Công | C7: Cơm trứng chiên | E7: TRUE | G7: =IF(C7<>"", M8, 0) -> 28 | J7: =SUM(G7:I7) -> 28 | L7: Tổng tiền | M7: =M19+M20 -> 252
A8: 7 | B8: Tùng | C8: đậu nhồi thụt | E8: TRUE | G8: =IF(C8<>"", M8, 0) -> 28 | J8: =SUM(G8:I8) -> 28 | L8: Mỗi người | M8: =ROUND(M7/M6,0) -> 28
A9: 8 | B9: Sỹ | C9: Cá ngừ kho tiêu | E9: TRUE | G9: =IF(C9<>"", M8, 0) -> 28 | J9: =SUM(G9:I9) -> 28
A10: 9 | B10: Việt | C10: đậu đũa xào thịt | E10: TRUE | G10: =IF(C10<>"", M8, 0) -> 28 | J10: =SUM(G10:I10) -> 28
A11: 10 | B11: Vinh | E11: FALSE | G11: =IF(C11<>"", M8, 0) -> 0 | J11: =SUM(G11:I11) -> 0 | L11: Tổng hợp chay
A12: 11 | B12: Hòa | C12: cơm thịt luộc cà pháo mắm tôm | E12: TRUE | G12: =IF(C12<>"", M8, 0) -> 28 | J12: =SUM(G12:I12) -> 28 | L12: Số người ăn | M12: =COUNTA(D2:D16) -> 0
A13: 12 | B13: Hieuthuhai | E13: FALSE | L13: Tổng tiền
A14: 13 | E14: FALSE | L14: Mỗi người | M14: =ROUNDUP(M13/M12,0) -> #DIV/0!
A15: 14 | E15: FALSE
A16: 15 | E16: FALSE
A17: ĐÃ ĐẶT
G18: =SUM(G2:G16) -> 252 | J18: =SUM(J2:J16) -> 252
E19: =COUNTIF(E2:E16,TRUE) -> 9 | L19: Trọng | M19: 252
L20: Hiếu
L21: Kiêm
L23: =SUM(M20:M22) -> 0

Sheet 05-06-2026
A1: STT | B1: Tên | C1: Tên món | D1: Tên món chay | F1: Note | G1: Link menu | H1: LINK MENU CHAY | I1: Món thêm | J1: Tổng
A2: {=_xlfn.SEQUENCE(15)} -> 1 | B2: Hiếu | C2: cơm gà phi lê | E2: FALSE | G2: =IF(C2<>"", M8, 0) -> 33 | J2: =SUM(G2:I2) -> 33
A3: 2 | B3: Trọng | E3: FALSE | G3: =IF(C3<>"", M8, 0) -> 0 | J3: =SUM(G3:I3) -> 0
A4: 3 | B4: Kiêm | C4: Cơm thịt nướng | E4: FALSE | F4: Cơm thêm + Trà tắc | G4: =IF(C4<>"", M8, 0) -> 33 | I4: 10 | J4: =SUM(G4:I4) -> 43
A5: 4 | B5: Anh Dũng | C5: cá | E5: FALSE | G5: =IF(C5<>"", M8, 0) -> 33 | J5: =SUM(G5:I5) -> 33 | L5: Tổng hợp
A6: 5 | B6: Hoàng Anh | E6: FALSE | G6: =IF(C6<>"", M8, 0) -> 0 | J6: =SUM(G6:I6) -> 0 | L6: Số người ăn | M6: =COUNTA(C2:C16) -> 4
A7: 6 | B7: Lê Thành Công | E7: FALSE | G7: =IF(C7<>"", M8, 0) -> 0 | J7: =SUM(G7:I7) -> 0 | L7: Tổng tiền | M7: =M19+M20-10 -> 133
A8: 7 | B8: Tùng | C8: gà fillet | E8: FALSE | G8: =IF(C8<>"", M8, 0) -> 33 | J8: =SUM(G8:I8) -> 33 | L8: Mỗi người | M8: =ROUND(M7/M6,0) -> 33
A9: 8 | B9: Sỹ | E9: FALSE | G9: =IF(C9<>"", M8, 0) -> 0 | J9: =SUM(G9:I9) -> 0
A10: 9 | B10: Việt | E10: FALSE | G10: =IF(C10<>"", M8, 0) -> 0 | J10: =SUM(G10:I10) -> 0
A11: 10 | B11: Vinh | E11: FALSE | G11: =IF(C11<>"", M8, 0) -> 0 | J11: =SUM(G11:I11) -> 0 | L11: Tổng hợp chay
A12: 11 | B12: Hòa | E12: FALSE | G12: =IF(C12<>"", M8, 0) -> 0 | J12: =SUM(G12:I12) -> 0 | L12: Số người ăn | M12: =COUNTA(D2:D16) -> 0
A13: 12 | B13: Hieuthuhai | E13: FALSE | L13: Tổng tiền
A14: 13 | E14: FALSE | L14: Mỗi người | M14: =ROUNDUP(M13/M12,0) -> #DIV/0!
A15: 14 | E15: FALSE
A16: 15 | E16: FALSE
A17: Đã đặt
G18: =SUM(G2:G16) -> 132 | J18: =SUM(J2:J16) -> 142
E19: =COUNTIF(E2:E16,TRUE) -> 0 | L19: Trọng
L20: Hiếu | M20: 143
L21: Kiêm
L23: =SUM(M20:M22) -> 143

Sheet 04-06-2026
A1: STT | B1: Tên | C1: Tên món | D1: Tên món chay | F1: Note | G1: Link menu | H1: LINK MENU CHAY | I1: Món thêm | J1: Tổng
A2: {=_xlfn.SEQUENCE(15)} -> 1 | B2: Hiếu | C2: Cơm sụn xào chua ngọt | E2: FALSE | G2: =IF(C2<>"", M8, 0) -> 25 | J2: =SUM(G2:I2) -> 25
A3: 2 | B3: Trọng | C3: Cơm sụn xào chua ngọt | E3: FALSE | G3: =IF(C3<>"", M8, 0) -> 25 | J3: =SUM(G3:I3) -> 25
A4: 3 | B4: Kiêm | C4: Cơm gà phi lê | E4: FALSE | F4: Cơm thêm + Trà tắc | G4: =IF(C4<>"", M8, 0) -> 25 | I4: 10 | J4: =SUM(G4:I4) -> 35
A5: 4 | B5: Anh Dũng | C5: Cá | E5: FALSE | G5: =IF(C5<>"", M8, 0) -> 25 | J5: =SUM(G5:I5) -> 25 | L5: Tổng hợp
A6: 5 | B6: Hoàng Anh | E6: FALSE | G6: =IF(C6<>"", M8, 0) -> 0 | J6: =SUM(G6:I6) -> 0 | L6: Số người ăn | M6: =COUNTA(C2:C16) -> 8
A7: 6 | B7: Lê Thành Công | C7: Cơm gà fillet | E7: TRUE | F7: trà tắc | G7: =IF(C7<>"", M8, 0) -> 25 | I7: 10 | J7: =SUM(G7:I7) -> 35 | L7: Tổng tiền | M7: =M19+M20-20 -> 203
A8: 7 | B8: Tùng | C8: gà fillet | E8: TRUE | G8: =IF(C8<>"", M8, 0) -> 25 | J8: =SUM(G8:I8) -> 25 | L8: Mỗi người | M8: =ROUND(M7/M6,0) -> 25
A9: 8 | B9: Sỹ | C9: Cơm bò kho | E9: TRUE | G9: =IF(C9<>"", M8, 0) -> 25 | J9: =SUM(G9:I9) -> 25
A10: 9 | B10: Việt | C10: cum đùi gà | E10: TRUE | G10: =IF(C10<>"", M8, 0) -> 25 | J10: =SUM(G10:I10) -> 25
A11: 10 | B11: Vinh | E11: FALSE | G11: =IF(C11<>"", M8, 0) -> 0 | J11: =SUM(G11:I11) -> 0 | L11: Tổng hợp chay
A12: 11 | B12: Hòa | E12: FALSE | G12: =IF(C12<>"", M8, 0) -> 0 | J12: =SUM(G12:I12) -> 0 | L12: Số người ăn | M12: =COUNTA(D2:D16) -> 0
A13: 12 | B13: Hieuthuhai | E13: FALSE | L13: Tổng tiền
A14: 13 | E14: FALSE | L14: Mỗi người | M14: =ROUNDUP(M13/M12,0) -> #DIV/0!
A15: 14 | E15: FALSE
A16: 15 | E16: FALSE
G18: =SUM(G2:G16) -> 200 | J18: =SUM(J2:J16) -> 220
E19: =COUNTIF(E2:E16,TRUE) -> 4 | L19: Trọng | M19: 223
L20: Hiếu
L21: Kiêm
L23: =SUM(M20:M22) -> 0

Sheet 03-06-2026
A1: STT | B1: Tên | C1: Tên món | D1: Tên món chay | F1: Note | G1: Link menu | H1: LINK MENU CHAY | I1: Món thêm | J1: Tổng
A2: {=_xlfn.SEQUENCE(15)} -> 1 | B2: Hiếu | C2: cơm gà phi lê | E2: TRUE | G2: =IF(C2<>"", M8, 0) -> 25 | J2: =SUM(G2:I2) -> 25
A3: 2 | B3: Trọng | C3: cơm gà phi lê | E3: TRUE | G3: =IF(C3<>"", M8, 0) -> 25 | J3: =SUM(G3:I3) -> 25
A4: 3 | B4: Kiêm | C4: cơm gà phi lê | E4: TRUE | G4: =IF(C4<>"", M8, 0) -> 25 | J4: =SUM(G4:I4) -> 25
A5: 4 | B5: Anh Dũng | C5: cá | E5: TRUE | G5: =IF(C5<>"", M8, 0) -> 25 | J5: =SUM(G5:I5) -> 25 | L5: Tổng hợp
A6: 5 | B6: Hoàng Anh | C6: xíu mại trứng cút | E6: TRUE | G6: =IF(C6<>"", M8, 0) -> 25 | J6: =SUM(G6:I6) -> 25 | L6: Số người ăn | M6: =COUNTA(C2:C16) -> 8
A7: 6 | B7: Lê Thành Công | C7: cơm gà phi lê | E7: TRUE | G7: =IF(C7<>"", M8, 0) -> 25 | J7: =SUM(G7:I7) -> 25 | L7: Tổng tiền | M7: =M19+M20 -> 203
A8: 7 | B8: Tùng | E8: FALSE | G8: =IF(C8<>"", M8, 0) -> 0 | J8: =SUM(G8:I8) -> 0 | L8: Mỗi người | M8: =ROUND(M7/M6,0) -> 25
A9: 8 | B9: Sỹ | C9: Xíu mại trứng cút | E9: TRUE | G9: =IF(C9<>"", M8, 0) -> 25 | J9: =SUM(G9:I9) -> 25
A10: 9 | B10: Việt | C10: cơm gà chiên nước mắm | E10: TRUE | G10: =IF(C10<>"", M8, 0) -> 25 | J10: =SUM(G10:I10) -> 25
A11: 10 | B11: Vinh | E11: FALSE | G11: =IF(C11<>"", M8, 0) -> 0 | J11: =SUM(G11:I11) -> 0 | L11: Tổng hợp chay
A12: 11 | B12: Hòa | E12: FALSE | G12: =IF(C12<>"", M8, 0) -> 0 | J12: =SUM(G12:I12) -> 0 | L12: Số người ăn | M12: =COUNTA(D2:D16) -> 0
A13: 12 | B13: Hieuthuhai | E13: FALSE | L13: Tổng tiền
A14: 13 | E14: FALSE | L14: Mỗi người | M14: =ROUNDUP(M13/M12,0) -> #DIV/0!
A15: 14 | E15: FALSE
A16: 15 | E16: FALSE
A17: ĐÃ ĐẶT
G18: =SUM(G2:G16) -> 200 | J18: =SUM(J2:J16) -> 200
E19: =COUNTIF(E2:E16,TRUE) -> 8 | L19: Trọng | M19: 203
L20: Hiếu
L21: Kiêm
L23: =SUM(M20:M22) -> 0

Sheet 02-06-2026
A1: STT | B1: Tên | C1: Tên món | D1: Tên món chay | F1: Note | G1: Link menu | H1: LINK MENU CHAY | I1: Món thêm | J1: Tổng
A2: {=_xlfn.SEQUENCE(15)} -> 1 | B2: Hiếu | C2: cơm canh xương hầm củ | E2: FALSE | G2: =IF(C2<>"", M8, 0) -> 29 | J2: =SUM(G2:I2) -> 29
A3: 2 | B3: Trọng | C3: thịt kho trứng | E3: FALSE | G3: =IF(C3<>"", M8, 0) -> 29 | J3: =SUM(G3:I3) -> 29
A4: 3 | B4: Kiêm | C4: Cơm thịt nướng | E4: FALSE | F4: Cơm thêm + Trà tắc | G4: =IF(C4<>"", M8, 0) -> 29 | I4: 10 | J4: =SUM(G4:I4) -> 39
A5: 4 | B5: Anh Dũng | C5: cá | E5: FALSE | G5: =IF(C5<>"", M8, 0) -> 29 | J5: =SUM(G5:I5) -> 29 | L5: Tổng hợp
A6: 5 | B6: Hoàng Anh | E6: FALSE | G6: =IF(C6<>"", M8, 0) -> 0 | J6: =SUM(G6:I6) -> 0 | L6: Số người ăn | M6: =COUNTA(C2:C16) -> 9
A7: 6 | B7: Lê Thành Công | C7: Bún thị nướng | E7: TRUE | F7: Thịt nạc | G7: =IF(C7<>"", M8, 0) -> 29 | J7: =SUM(G7:I7) -> 29 | L7: Tổng tiền | M7: =M19+M20-10 -> 259
A8: 7 | B8: Tùng | C8: thịt luộc cà | E8: TRUE | G8: =IF(C7<>"", M8, 0) -> 29 | J8: =SUM(G8:I8) -> 29 | L8: Mỗi người | M8: =ROUND(M7/M6,0) -> 29
A9: 8 | B9: Sỹ | C9: Thịt luộc cà pháo | E9: TRUE | F9: Mắm nêm không muốn làm căn phòng này bốc mùi bằng mắm tôm đâu ! | G9: =IF(C9<>"", M8, 0) -> 29 | J9: =SUM(G9:I9) -> 29
A10: 9 | B10: Việt | C10: Cơm đậu hủ dồn thịt | E10: TRUE | G10: =IF(C10<>"", M8, 0) -> 29 | J10: =SUM(G10:I10) -> 29
A11: 10 | B11: Vinh | E11: TRUE | G11: =IF(C11<>"", M8, 0) -> 0 | J11: =SUM(G11:I11) -> 0 | L11: Tổng hợp chay
A12: 11 | B12: Hòa | C12: Cơm thịt luộc cà pháo | E12: TRUE | G12: =IF(C12<>"", M8, 0) -> 29 | J12: =SUM(G12:I12) -> 29 | L12: Số người ăn | M12: =COUNTA(D2:D16) -> 0
A13: 12 | B13: Hieuthuhai | E13: FALSE | L13: Tổng tiền
A14: 13 | E14: FALSE | L14: Mỗi người | M14: =ROUNDUP(M13/M12,0) -> #DIV/0!
A15: 14 | E15: FALSE
A16: 15 | E16: FALSE
G18: =SUM(G2:G16) -> 261 | J18: =SUM(J2:J16) -> 271
E19: =COUNTIF(E2:E16,TRUE) -> 6 | L19: Trọng | M19: 269
L20: Hiếu
L21: Kiêm
L23: =SUM(M20:M22) -> 0

Sheet 01-06-2026
A1: STT | B1: Tên | C1: Tên món | D1: Tên món chay | F1: Note | G1: Link menu | H1: LINK MENU CHAY | I1: Món thêm | J1: Tổng
A2: {=_xlfn.SEQUENCE(15)} -> 1 | B2: Hiếu | C2: cơm thịt xào mướp | E2: TRUE | G2: =IF(C2<>"", M8, 0) -> 25 | J2: =SUM(G2:I2) -> 25
A3: 2 | B3: Trọng | C3: cơm thịt xào mướp | E3: TRUE | G3: =IF(C3<>"", M8, 0) -> 25 | I3: 10 | J3: =SUM(G3:I3) -> 35
A4: 3 | B4: Kiêm | C4: Cơm xíu mại | E4: TRUE | F4: Cơm thêm | G4: =IF(C4<>"", M8, 0) -> 25 | J4: =SUM(G4:I4) -> 25
A5: 4 | B5: Anh Dũng | C5: Con cá | E5: TRUE | G5: =IF(C5<>"", M8, 0) -> 25 | J5: =SUM(G5:I5) -> 25 | L5: Tổng hợp
A6: 5 | B6: Hoàng Anh | C6: cơm gà fillet | E6: TRUE | G6: =IF(C6<>"", M8, 0) -> 25 | J6: =SUM(G6:I6) -> 25 | L6: Số người ăn | M6: =COUNTA(C2:C16) -> 9
A7: 6 | B7: Lê Thành Công | C7: tôm | E7: TRUE | F7: Lấy thịt nạc | G7: =IF(C7<>"", M8, 0) -> 25 | I7: 10 | J7: =SUM(G7:I7) -> 35 | L7: Tổng tiền | M7: =M19+M20-20 -> 229
A8: 7 | B8: Tùng | C8: cơm gà fillet | E8: TRUE | G8: =IF(C8<>"", M8, 0) -> 25 | J8: =SUM(G8:I8) -> 25 | L8: Mỗi người | M8: =ROUND(M7/M6,0) -> 25
A9: 8 | B9: Sỹ | C9: Gà kho sả | E9: TRUE | G9: =IF(C9<>"", M8, 0) -> 25 | J9: =SUM(G9:I9) -> 25
A10: 9 | B10: Việt | E10: TRUE | F10: Bọc cơm thêm pls, kêu ngta cho cái thìa nữa | G10: =IF(C10<>"", M8, 0) -> 0 | J10: =SUM(G10:I10) -> 0
A11: 10 | B11: Vinh | E11: FALSE | G11: =IF(C11<>"", M8, 0) -> 0 | J11: =SUM(G11:I11) -> 0 | L11: Tổng hợp chay
A12: 11 | B12: Hòa | C12: Cơm thịt luộc cà pháo | E12: TRUE | G12: =IF(C12<>"", M8, 0) -> 25 | J12: =SUM(G12:I12) -> 25 | L12: Số người ăn | M12: =COUNTA(D2:D16) -> 0
A13: 12 | B13: Hieuthuhai | E13: FALSE | L13: Tổng tiền
A14: 13 | E14: FALSE | L14: Mỗi người | M14: =ROUNDUP(M13/M12,0) -> #DIV/0!
A15: 14 | E15: FALSE
A16: 15 | E16: FALSE
G18: =SUM(G2:G16) -> 225 | J18: =SUM(J2:J16) -> 245
E19: =COUNTIF(E2:E16,TRUE) -> 10 | L19: Trọng | M19: 249
L20: Hiếu
L21: Kiêm
B22: CHƯƠNG TRÌNH ĐẶT CƠM NGÀY HỘI THIẾU NHI BÉ KHỎE BÉ NGOAN
L23: =SUM(M20:M22) -> 0

Sheet 29-05-2026
A1: STT | B1: Tên | C1: Tên món | D1: Tên món chay | F1: Note | G1: Link menu | H1: LINK MENU CHAY | I1: Món thêm | J1: Tổng
A2: {=_xlfn.SEQUENCE(15)} -> 1 | B2: Hiếu | C2: bún mắm nêm | E2: FALSE | G2: =IF(C2<>"", M8, 0) -> 32 | H2: =IF(D2<>"", M14, 0) -> 0 | J2: =SUM(G2:I2) -> 32
A3: 2 | B3: Trọng | E3: FALSE | G3: =IF(C3<>"", M8, 0) -> 0 | H3: =IF(D3<>"", M14, 0) -> 0 | J3: =SUM(G3:I3) -> 0
A4: 3 | B4: Kiêm | C4: Cơm gà phi lle | E4: FALSE | F4: Cơm thêm + trà tắc | G4: =IF(C4<>"", M8, 0) -> 32 | H4: =IF(D4<>"", M14, 0) -> 0 | I4: 15 | J4: =SUM(G4:I4) -> 47
A5: 4 | B5: Anh Dũng | C5: bún thịt nướng | E5: FALSE | G5: =IF(C5<>"", M8, 0) -> 32 | H5: =IF(D5<>"", M14, 0) -> 0 | J5: =SUM(G5:I5) -> 32 | L5: Tổng hợp
A6: 5 | B6: Hoàng Anh | E6: FALSE | G6: =IF(C6<>"", M8, 0) -> 0 | H6: =IF(D6<>"", M14, 0) -> 0 | J6: =SUM(G6:I6) -> 0 | L6: Số người ăn | M6: =COUNTA(C2:C16) -> 4
A7: 6 | B7: Lê Thành Công | E7: FALSE | G7: =IF(C7<>"", M8, 0) -> 0 | H7: =IF(D7<>"", M14, 0) -> 0 | J7: =SUM(G7:I7) -> 0 | L7: Tổng tiền | M7: =M19+M20-15 -> 126
A8: 7 | B8: Tùng | E8: FALSE | G8: =IF(C8<>"", M8, 0) -> 0 | H8: =IF(D8<>"", M14, 0) -> 0 | J8: =SUM(G8:I8) -> 0 | L8: Mỗi người | M8: =ROUND(M7/M6,0) -> 32
A9: 8 | B9: Sỹ | C9: Cơm bò kho | E9: FALSE | G9: =IF(C9<>"", M8, 0) -> 32 | H9: =IF(D9<>"", M14, 0) -> 0 | J9: =SUM(G9:I9) -> 32
A10: 9 | B10: Việt | E10: FALSE | G10: =IF(C10<>"", M8, 0) -> 0 | H10: =IF(D10<>"", M14, 0) -> 0 | J10: =SUM(G10:I10) -> 0
A11: 10 | B11: Vinh | E11: FALSE | G11: =IF(C11<>"", M8, 0) -> 0 | H11: =IF(D11<>"", M14, 0) -> 0 | J11: =SUM(G11:I11) -> 0 | L11: Tổng hợp chay
A12: 11 | B12: Hiếu thứ 2 | E12: FALSE | G12: =IF(C12<>"", M8, 0) -> 0 | H12: =IF(D12<>"", M14, 0) -> 0 | J12: =SUM(G12:I12) -> 0 | L12: Số người ăn | M12: =COUNTA(D2:D16) -> 0
A13: 12 | E13: FALSE | G13: =IF(C13<>"", M8, 0) -> 0 | H13: =IF(D13<>"", M14, 0) -> 0 | J13: =SUM(G13:I13) -> 0 | L13: Tổng tiền
A14: 13 | E14: FALSE | G14: =IF(C14<>"", M8, 0) -> 0 | H14: =IF(D14<>"", M14, 0) -> 0 | J14: =SUM(G14:I14) -> 0 | L14: Mỗi người | M14: =ROUNDUP(M13/M12,0) -> #DIV/0!
A15: 14 | E15: FALSE | G15: =IF(C15<>"", M8, 0) -> 0 | H15: =IF(D15<>"", M14, 0) -> 0 | J15: =SUM(G15:I15) -> 0
A16: 15 | E16: FALSE | G16: =IF(C16<>"", M8, 0) -> 0 | H16: =IF(D16<>"", M14, 0) -> 0 | J16: =SUM(G16:I16) -> 0
A17: ĐÃ ĐẶT
G18: =SUM(G2:G16) -> 128 | J18: =SUM(J2:J16) -> 143
E19: =COUNTIF(E2:E16,TRUE) -> 0 | L19: Trọng | M19: 141
L20: Hiếu
L21: Kiêm
L23: =SUM(M20:M22) -> 0

Sheet 28-05-2026
A1: STT | B1: Tên | C1: Tên món | D1: Tên món chay | F1: Note | G1: Link menu | H1: LINK MENU CHAY | I1: Món thêm | J1: Tổng
A2: {=_xlfn.SEQUENCE(15)} -> 1 | B2: Hiếu | C2: cơm | E2: FALSE | G2: =IF(C2<>"", M8, 0) -> 27 | H2: =IF(D2<>"", M14, 0) -> 0 | J2: =SUM(G2:I2) -> 27
A3: 2 | B3: Trọng | C3: gà phi lê | E3: FALSE | G3: =IF(C3<>"", M8, 0) -> 27 | H3: =IF(D3<>"", M14, 0) -> 0 | J3: =SUM(G3:I3) -> 27
A4: 3 | B4: Kiêm | C4: Cơm thịt nướng | E4: FALSE | F4: Cơm thêm | G4: =IF(C4<>"", M8, 0) -> 27 | H4: =IF(D4<>"", M14, 0) -> 0 | J4: =SUM(G4:I4) -> 27
A5: 4 | B5: Anh Dũng | C5: cá | E5: FALSE | G5: =IF(C5<>"", M8, 0) -> 27 | H5: =IF(D5<>"", M14, 0) -> 0 | J5: =SUM(G5:I5) -> 27 | L5: Tổng hợp
A6: 5 | B6: Hoàng Anh | E6: FALSE | G6: =IF(C6<>"", M8, 0) -> 0 | H6: =IF(D6<>"", M14, 0) -> 0 | J6: =SUM(G6:I6) -> 0 | L6: Số người ăn | M6: =COUNTA(C2:C16) -> 9
A7: 6 | B7: Lê Thành Công | C7: gà phi lê | E7: TRUE | G7: =IF(C7<>"", M8, 0) -> 27 | H7: =IF(D7<>"", M14, 0) -> 0 | J7: =SUM(G7:I7) -> 27 | L7: Tổng tiền | M7: =M19+M20 -> 239
A8: 7 | B8: Tùng | C8: bún thịt nứng | E8: TRUE | G8: =IF(C8<>"", M8, 0) -> 27 | H8: =IF(D8<>"", M14, 0) -> 0 | J8: =SUM(G8:I8) -> 27 | L8: Mỗi người | M8: =ROUND(M7/M6,0) -> 27
A9: 8 | B9: Sỹ | C9: Ếch xào xả ớt | E9: TRUE | G9: =IF(C9<>"", M8, 0) -> 27 | H9: =IF(D9<>"", M14, 0) -> 0 | J9: =SUM(G9:I9) -> 27
A10: 9 | B10: Việt | E10: FALSE | F10: 1 hộp cơm không có đồ ăn | G10: =IF(C10<>"", M8, 0) -> 0 | H10: =IF(D10<>"", M14, 0) -> 0 | J10: =SUM(G10:I10) -> 0
A11: 10 | B11: Vinh | C11: Thịt kho đậu hủ | E11: TRUE | G11: =IF(C11<>"", M8, 0) -> 27 | H11: =IF(D11<>"", M14, 0) -> 0 | J11: =SUM(G11:I11) -> 27 | L11: Tổng hợp chay
A12: 11 | B12: Hiếu thứ 2 | C12: Cơm thịt kho cải chua | E12: TRUE | G12: =IF(C12<>"", M8, 0) -> 27 | H12: =IF(D12<>"", M14, 0) -> 0 | J12: =SUM(G12:I12) -> 27 | L12: Số người ăn | M12: =COUNTA(D2:D16) -> 0
A13: 12 | E13: FALSE | G13: =IF(C13<>"", M8, 0) -> 0 | H13: =IF(D13<>"", M14, 0) -> 0 | J13: =SUM(G13:I13) -> 0 | L13: Tổng tiền
A14: 13 | E14: FALSE | G14: =IF(C14<>"", M8, 0) -> 0 | H14: =IF(D14<>"", M14, 0) -> 0 | J14: =SUM(G14:I14) -> 0 | L14: Mỗi người | M14: =ROUNDUP(M13/M12,0) -> #DIV/0!
A15: 14 | E15: FALSE | G15: =IF(C15<>"", M8, 0) -> 0 | H15: =IF(D15<>"", M14, 0) -> 0 | J15: =SUM(G15:I15) -> 0
A16: 15 | E16: FALSE | G16: =IF(C16<>"", M8, 0) -> 0 | H16: =IF(D16<>"", M14, 0) -> 0 | J16: =SUM(G16:I16) -> 0
A17: ĐÃ ĐẶTK
G18: =SUM(G2:G16) -> 243 | J18: =SUM(J2:J16) -> 243
E19: =COUNTIF(E2:E16,TRUE) -> 5 | L19: Trọng | M19: 239
L20: Hiếu
L21: Kiêm
L23: =SUM(M20:M22) -> 0

Sheet 27-05-2026
A1: STT | B1: Tên | C1: Tên món | D1: Tên món chay | F1: Note | G1: Link menu | H1: LINK MENU CHAY | I1: Món thêm | J1: Tổng
A2: {=_xlfn.SEQUENCE(15)} -> 1 | B2: Hiếu | C2: cơm xương giò kho giả cầy | E2: TRUE | G2: =IF(C2<>"", M8, 0) -> 29 | H2: =IF(D2<>"", M14, 0) -> 0 | J2: =SUM(G2:I2) -> 29
A3: 2 | B3: Trọng | C3: . | E3: TRUE | G3: =IF(C3<>"", M8, 0) -> 29 | H3: =IF(D3<>"", M14, 0) -> 0 | J3: =SUM(G3:I3) -> 29
A4: 3 | B4: Kiêm | E4: FALSE | G4: =IF(C4<>"", M8, 0) -> 0 | H4: =IF(D4<>"", M14, 0) -> 0 | J4: =SUM(G4:I4) -> 0
A5: 4 | B5: Anh Dũng | C5: cá | E5: TRUE | G5: =IF(C5<>"", M8, 0) -> 29 | H5: =IF(D5<>"", M14, 0) -> 0 | J5: =SUM(G5:I5) -> 29 | L5: Tổng hợp
A6: 5 | B6: Hoàng Anh | E6: FALSE | G6: =IF(C6<>"", M8, 0) -> 0 | H6: =IF(D6<>"", M14, 0) -> 0 | J6: =SUM(G6:I6) -> 0 | L6: Số người ăn | M6: =COUNTA(C2:C16) -> 5
A7: 6 | B7: Lê Thành Công | C7: Cơm thịt khi trưng | E7: TRUE | F7: chỉ lấy trứng :V | G7: =IF(C7<>"", M8, 0) -> 29 | H7: =IF(D7<>"", M14, 0) -> 0 | J7: =SUM(G7:I7) -> 29 | L7: Tổng tiền | M7: =M19+M20 -> 146
A8: 7 | B8: Tùng | E8: FALSE | G8: =IF(C8<>"", M8, 0) -> 0 | H8: =IF(D8<>"", M14, 0) -> 0 | J8: =SUM(G8:I8) -> 0 | L8: Mỗi người | M8: =ROUND(M7/M6,0) -> 29
A9: 8 | B9: Sỹ | E9: FALSE | G9: =IF(C9<>"", M8, 0) -> 0 | H9: =IF(D9<>"", M14, 0) -> 0 | J9: =SUM(G9:I9) -> 0
A10: 9 | B10: Việt | E10: FALSE | G10: =IF(C10<>"", M8, 0) -> 0 | H10: =IF(D10<>"", M14, 0) -> 0 | J10: =SUM(G10:I10) -> 0
A11: 10 | B11: Vinh | E11: FALSE | G11: =IF(C11<>"", M8, 0) -> 0 | H11: =IF(D11<>"", M14, 0) -> 0 | J11: =SUM(G11:I11) -> 0 | L11: Tổng hợp chay
A12: 11 | B12: Hiếu thứ 2 | C12: cơm cá hú kho | E12: TRUE | F12: cà pháo | G12: =IF(C12<>"", M8, 0) -> 29 | H12: =IF(D12<>"", M14, 0) -> 0 | J12: =SUM(G12:I12) -> 29 | L12: Số người ăn | M12: =COUNTA(D2:D16) -> 0
A13: 12 | E13: FALSE | G13: =IF(C13<>"", M8, 0) -> 0 | H13: =IF(D13<>"", M14, 0) -> 0 | J13: =SUM(G13:I13) -> 0 | L13: Tổng tiền
A14: 13 | E14: FALSE | G14: =IF(C14<>"", M8, 0) -> 0 | H14: =IF(D14<>"", M14, 0) -> 0 | J14: =SUM(G14:I14) -> 0 | L14: Mỗi người | M14: =ROUNDUP(M13/M12,0) -> #DIV/0!
A15: 14 | E15: FALSE | G15: =IF(C15<>"", M8, 0) -> 0 | H15: =IF(D15<>"", M14, 0) -> 0 | J15: =SUM(G15:I15) -> 0
A16: 15 | E16: FALSE | G16: =IF(C16<>"", M8, 0) -> 0 | H16: =IF(D16<>"", M14, 0) -> 0 | J16: =SUM(G16:I16) -> 0
A17: ĐÃ ĐẶT
G18: =SUM(G2:G16) -> 145 | J18: =SUM(J2:J16) -> 145
E19: =COUNTIF(E2:E16,TRUE) -> 5 | L19: Trọng | M19: 146
L20: Hiếu
L21: Kiêm
L23: =SUM(M20:M22) -> 0

Sheet 26-05-2026
A1: STT | B1: Tên | C1: Tên món | D1: Tên món chay | F1: Note | G1: Link menu | H1: LINK MENU CHAY | I1: Món thêm | J1: Tổng
A2: {=_xlfn.SEQUENCE(15)} -> 1 | B2: Hiếu | C2: Lươn kho sả ớt | E2: FALSE | G2: =IF(C2<>"", M8, 0) -> 29 | H2: =IF(D2<>"", M14, 0) -> 0 | J2: =SUM(G2:I2) -> 29
A3: 2 | B3: Trọng | E3: FALSE | G3: =IF(C3<>"", M8, 0) -> 0 | H3: =IF(D3<>"", M14, 0) -> 0 | J3: =SUM(G3:I3) -> 0
A4: 3 | B4: Kiêm | C4: Cơn xíu mại | E4: FALSE | G4: =IF(C4<>"", M8, 0) -> 29 | H4: =IF(D4<>"", M14, 0) -> 0 | J4: =SUM(G4:I4) -> 29
A5: 4 | B5: Anh Dũng | C5: Cá biển | E5: FALSE | G5: =IF(C5<>"", M8, 0) -> 29 | H5: =IF(D5<>"", M14, 0) -> 0 | J5: =SUM(G5:I5) -> 29 | L5: Tổng hợp
A6: 5 | B6: Hoàng Anh | E6: FALSE | G6: =IF(C6<>"", M8, 0) -> 0 | H6: =IF(D6<>"", M14, 0) -> 0 | J6: =SUM(G6:I6) -> 0 | L6: Số người ăn | M6: =COUNTA(C2:C16) -> 7
A7: 6 | B7: Lê Thành Công | C7: Lươn kho sả ớt | E7: FALSE | G7: =IF(C7<>"", M8, 0) -> 29 | H7: =IF(D7<>"", M14, 0) -> 0 | J7: =SUM(G7:I7) -> 29 | L7: Tổng tiền | M7: =M19+M20 -> 200
A8: 7 | B8: Tùng | C8: thịt xào măng cay | E8: FALSE | G8: =IF(C8<>"", M8, 0) -> 29 | H8: =IF(D8<>"", M14, 0) -> 0 | J8: =SUM(G8:I8) -> 29 | L8: Mỗi người | M8: =ROUND(M7/M6,0) -> 29
A9: 8 | B9: Sỹ | C9: Bún thịt nướng | E9: FALSE | G9: =IF(C9<>"", M8, 0) -> 29 | H9: =IF(D9<>"", M14, 0) -> 0 | J9: =SUM(G9:I9) -> 29
A10: 9 | B10: Việt | E10: FALSE | G10: =IF(C10<>"", M8, 0) -> 0 | H10: =IF(D10<>"", M14, 0) -> 0 | J10: =SUM(G10:I10) -> 0
A11: 10 | B11: Vinh | C11: Cơm thịt kho đậu hủ | E11: FALSE | G11: =IF(C11<>"", M8, 0) -> 29 | H11: =IF(D11<>"", M14, 0) -> 0 | J11: =SUM(G11:I11) -> 29 | L11: Tổng hợp chay
A12: 11 | E12: FALSE | G12: =IF(C6<>"", M11, 0) -> 0 | H12: =IF(D12<>"", M14, 0) -> 0 | J12: =SUM(G12:I12) -> 0 | L12: Số người ăn | M12: =COUNTA(D2:D16) -> 0
A13: 12 | E13: FALSE | G13: =IF(C13<>"", M8, 0) -> 0 | H13: =IF(D13<>"", M14, 0) -> 0 | J13: =SUM(G13:I13) -> 0 | L13: Tổng tiền
A14: 13 | E14: FALSE | G14: =IF(C14<>"", M8, 0) -> 0 | H14: =IF(D14<>"", M14, 0) -> 0 | J14: =SUM(G14:I14) -> 0 | L14: Mỗi người | M14: =ROUNDUP(M13/M12,0) -> #DIV/0!
A15: 14 | E15: FALSE | G15: =IF(C15<>"", M8, 0) -> 0 | H15: =IF(D15<>"", M14, 0) -> 0 | J15: =SUM(G15:I15) -> 0
A16: 15 | E16: FALSE | G16: =IF(C16<>"", M8, 0) -> 0 | H16: =IF(D16<>"", M14, 0) -> 0 | J16: =SUM(G16:I16) -> 0
G18: =SUM(G2:G16) -> 203 | J18: =SUM(J2:J16) -> 203
E19: =COUNTIF(E2:E16,TRUE) -> 0 | L19: Trọng
L20: Hiếu | M20: 200
L21: Kiêm
L23: =SUM(M20:M22) -> 200

Sheet 25-05-2026 
A1: STT | B1: Tên | C1: Tên món | D1: Tên món chay | F1: Note | G1: Link menu | H1: LINK MENU CHAY | I1: Món thêm | J1: Tổng
A2: {=_xlfn.SEQUENCE(15)} -> 1 | B2: Hiếu | C2: cơm canh khổ qua | E2: FALSE | G2: =IF(C2<>"", M8, 0) -> 26 | H2: =IF(D2<>"", M14, 0) -> 0 | J2: =SUM(G2:I2) -> 26
A3: 2 | B3: Trọng | E3: FALSE | G3: =IF(C3<>"", M8, 0) -> 0 | H3: =IF(D3<>"", M14, 0) -> 0 | J3: =SUM(G3:I3) -> 0
A4: 3 | B4: Kiêm | C4: Gà phi lê | E4: TRUE | F4: Cơm thêm + trà tắc | G4: =IF(C4<>"", M8, 0) -> 26 | H4: =IF(D4<>"", M14, 0) -> 0 | I4: 10 | J4: =SUM(G4:I4) -> 36
A5: 4 | B5: Anh Dũng | C5: cas | E5: TRUE | G5: =IF(C5<>"", M8, 0) -> 26 | H5: =IF(D5<>"", M14, 0) -> 0 | J5: =SUM(G5:I5) -> 26 | L5: Tổng hợp
A6: 5 | B6: Hoàng Anh | E6: FALSE | G6: =IF(C6<>"", M8, 0) -> 0 | H6: =IF(D6<>"", M14, 0) -> 0 | J6: =SUM(G6:I6) -> 0 | L6: Số người ăn | M6: =COUNTA(C2:C16) -> 7
A7: 6 | B7: Lê Thành Công | C7: Cơm cá biển chiên sốt mắm | E7: TRUE | G7: =IF(C7<>"", M8, 0) -> 26 | H7: =IF(D7<>"", M14, 0) -> 0 | J7: =SUM(G7:I7) -> 26 | L7: Tổng tiền | M7: =M19-10 -> 180
A8: 7 | B8: Tùng | E8: FALSE | G8: =IF(C8<>"", M8, 0) -> 0 | H8: =IF(D8<>"", M14, 0) -> 0 | J8: =SUM(G8:I8) -> 0 | L8: Mỗi người | M8: =ROUND(M7/M6,0) -> 26
A9: 8 | B9: Sỹ | C9: Lươn kho xả ớt | E9: TRUE | G9: =IF(C9<>"", M8, 0) -> 26 | H9: =IF(D9<>"", M14, 0) -> 0 | J9: =SUM(G9:I9) -> 26
A10: 9 | B10: Việt | C10: Cơm thịt nướng | E10: TRUE | G10: =IF(C10<>"", M8, 0) -> 26 | H10: =IF(D10<>"", M14, 0) -> 0 | J10: =SUM(G10:I10) -> 26
A11: 10 | B11: Vinh | C11: Cơm cá biển chiên sốt mắm | E11: TRUE | G11: =IF(C11<>"", M8, 0) -> 26 | H11: =IF(D11<>"", M14, 0) -> 0 | J11: =SUM(G11:I11) -> 26 | L11: Tổng hợp chay
A12: 11 | E12: FALSE | G12: =IF(C6<>"", M11, 0) -> 0 | H12: =IF(D12<>"", M14, 0) -> 0 | J12: =SUM(G12:I12) -> 0 | L12: Số người ăn | M12: =COUNTA(D2:D16) -> 0
A13: 12 | E13: FALSE | G13: =IF(C13<>"", M8, 0) -> 0 | H13: =IF(D13<>"", M14, 0) -> 0 | J13: =SUM(G13:I13) -> 0 | L13: Tổng tiền
A14: 13 | E14: FALSE | G14: =IF(C14<>"", M8, 0) -> 0 | H14: =IF(D14<>"", M14, 0) -> 0 | J14: =SUM(G14:I14) -> 0 | L14: Mỗi người | M14: =ROUNDUP(M13/M12,0) -> #DIV/0!
A15: 14 | E15: FALSE | G15: =IF(C15<>"", M8, 0) -> 0 | H15: =IF(D15<>"", M14, 0) -> 0 | J15: =SUM(G15:I15) -> 0
A16: 15 | E16: FALSE | G16: =IF(C16<>"", M8, 0) -> 0 | H16: =IF(D16<>"", M14, 0) -> 0 | J16: =SUM(G16:I16) -> 0
G18: =SUM(G2:G16) -> 182 | J18: =SUM(J2:J16) -> 192
E19: =COUNTIF(E2:E16,TRUE) -> 6 | L19: Trọng | M19: 190
L20: Hiếu
L21: Kiêm
L23: =SUM(M20:M22) -> 0

Sheet 21-05-2026
A1: STT | B1: Tên | C1: Tên món | D1: Tên món chay | F1: Note | G1: LINK MENU | H1: LINK MENU CHAY | I1: Món thêm | J1: Tổng
A2: {=_xlfn.SEQUENCE(15)} -> 1 | B2: Hiếu | C2: thịt luộc mắm nêm | E2: TRUE | G2: =IF(C2<>"", M8, 0) -> 26 | H2: =IF(D2<>"", M14, 0) -> 0 | J2: =SUM(G2:I2) -> 26
A3: 2 | B3: Trọng | C3: phílee | E3: TRUE | G3: =IF(C3<>"", M8, 0) -> 26 | H3: =IF(D3<>"", M14, 0) -> 0 | J3: =SUM(G3:I3) -> 26
A4: 3 | B4: Kiêm | E4: FALSE | G4: =IF(C4<>"", M8, 0) -> 0 | H4: =IF(D4<>"", M14, 0) -> 0 | J4: =SUM(G4:I4) -> 0
A5: 4 | B5: Anh Dũng | C5: cá | E5: TRUE | G5: =IF(C5<>"", M8, 0) -> 26 | H5: =IF(D5<>"", M14, 0) -> 0 | J5: =SUM(G5:I5) -> 26 | L5: Tổng hợp
A6: 5 | B6: Hoàng Anh | E6: FALSE | G6: =IF(C6<>"", M8, 0) -> 0 | H6: =IF(D6<>"", M14, 0) -> 0 | J6: =SUM(G6:I6) -> 0 | L6: Số người ăn | M6: =COUNTA(C2:C16) -> 6
A7: 6 | B7: Lê Thành Công | C7: Cơm cá biển chiên sốt mắm | E7: TRUE | G7: =IF(C7<>"", M8, 0) -> 26 | H7: =IF(D7<>"", M14, 0) -> 0 | J7: =SUM(G7:I7) -> 26 | L7: Tổng tiền | M7: =M19 -> 156
A8: 7 | B8: Tùng | E8: FALSE | G8: =IF(C8<>"", M8, 0) -> 0 | H8: =IF(D8<>"", M14, 0) -> 0 | J8: =SUM(G8:I8) -> 0 | L8: Mỗi người | M8: =ROUND(M7/M6,0) -> 26
A9: 8 | B9: Sỹ | C9: Cơm xíu mại | E9: TRUE | G9: =IF(C9<>"", M8, 0) -> 26 | H9: =IF(D9<>"", M14, 0) -> 0 | J9: =SUM(G9:I9) -> 26
A10: 9 | B10: Việt | C10: Cơm thịt nướng | E10: TRUE | G10: =IF(C10<>"", M8, 0) -> 26 | H10: =IF(D10<>"", M14, 0) -> 0 | J10: =SUM(G10:I10) -> 26
A11: 10 | B11: Vinh | E11: FALSE | G11: =IF(C11<>"", M8, 0) -> 0 | H11: =IF(D11<>"", M14, 0) -> 0 | J11: =SUM(G11:I11) -> 0 | L11: Tổng hợp chay
A12: 11 | E12: FALSE | G12: =IF(C6<>"", M11, 0) -> 0 | H12: =IF(D12<>"", M14, 0) -> 0 | J12: =SUM(G12:I12) -> 0 | L12: Số người ăn | M12: =COUNTA(D2:D16) -> 0
A13: 12 | E13: FALSE | G13: =IF(C13<>"", M8, 0) -> 0 | H13: =IF(D13<>"", M14, 0) -> 0 | J13: =SUM(G13:I13) -> 0 | L13: Tổng tiền
A14: 13 | E14: FALSE | G14: =IF(C14<>"", M8, 0) -> 0 | H14: =IF(D14<>"", M14, 0) -> 0 | J14: =SUM(G14:I14) -> 0 | L14: Mỗi người | M14: =ROUNDUP(M13/M12,0) -> #DIV/0!
A15: 14 | E15: FALSE | G15: =IF(C15<>"", M8, 0) -> 0 | H15: =IF(D15<>"", M14, 0) -> 0 | J15: =SUM(G15:I15) -> 0
A16: 15 | E16: FALSE | G16: =IF(C16<>"", M8, 0) -> 0 | H16: =IF(D16<>"", M14, 0) -> 0 | J16: =SUM(G16:I16) -> 0
G18: =SUM(G2:G16) -> 156 | J18: =SUM(J2:J16) -> 156
E19: =COUNTIF(E2:E16,TRUE) -> 6 | L19: Trọng | M19: 156
L20: Hiếu
L21: Kiêm
L23: =SUM(M20:M22) -> 0

Sheet 20-05-2026
A1: STT | B1: Tên | C1: Tên món | D1: Tên món chay | F1: Note | G1: LINK MENU | H1: LINK MENU CHAY | I1: Món thêm | J1: Tổng
A2: {=_xlfn.SEQUENCE(15)} -> 1 | B2: Hiếu | C2: bún thịt nướng | E2: TRUE | G2: =IF(C2<>"", M8, 0) -> 27 | H2: =IF(D2<>"", M14, 0) -> 0 | J2: =SUM(G2:I2) -> 27
A3: 2 | B3: Trọng | E3: FALSE | G3: =IF(C3<>"", M8, 0) -> 0 | H3: =IF(D3<>"", M14, 0) -> 0 | J3: =SUM(G3:I3) -> 0
A4: 3 | B4: Kiêm | E4: FALSE | G4: =IF(C4<>"", M8, 0) -> 0 | H4: =IF(D4<>"", M14, 0) -> 0 | J4: =SUM(G4:I4) -> 0
A5: 4 | B5: Anh Dũng | C5: cá | E5: TRUE | G5: =IF(C5<>"", M8, 0) -> 27 | H5: =IF(D5<>"", M14, 0) -> 0 | J5: =SUM(G5:I5) -> 27 | L5: Tổng hợp
A6: 5 | B6: Hoàng Anh | E6: FALSE | G6: =IF(C6<>"", M8, 0) -> 0 | H6: =IF(D6<>"", M14, 0) -> 0 | J6: =SUM(G6:I6) -> 0 | L6: Số người ăn | M6: =COUNTA(C2:C16) -> 6
A7: 6 | B7: Lê Thành Công | C7: Cơm đậu hủ dồn thịt | E7: TRUE | G7: =IF(C7<>"", M8, 0) -> 27 | H7: =IF(D7<>"", M14, 0) -> 0 | J7: =SUM(G7:I7) -> 27 | L7: Tổng tiền | M7: =M19 -> 163
A8: 7 | B8: Tùng | C8: bún thịt nướng | E8: TRUE | G8: =IF(C8<>"", M8, 0) -> 27 | H8: =IF(D8<>"", M14, 0) -> 0 | J8: =SUM(G8:I8) -> 27 | L8: Mỗi người | M8: =ROUND(M7/M6,0) -> 27
A9: 8 | B9: Sỹ | C9: Gà kho xả | E9: TRUE | G9: =IF(C9<>"", M8, 0) -> 27 | H9: =IF(D9<>"", M14, 0) -> 0 | J9: =SUM(G9:I9) -> 27
A10: 9 | B10: Việt | C10: bún thịt nướng | E10: TRUE | G10: =IF(C10<>"", M8, 0) -> 27 | H10: =IF(D10<>"", M14, 0) -> 0 | J10: =SUM(G10:I10) -> 27
A11: 10 | B11: Vinh | E11: FALSE | G11: =IF(C11<>"", M8, 0) -> 0 | H11: =IF(D11<>"", M14, 0) -> 0 | J11: =SUM(G11:I11) -> 0 | L11: Tổng hợp chay
A12: 11 | E12: FALSE | G12: =IF(C6<>"", M11, 0) -> 0 | H12: =IF(D12<>"", M14, 0) -> 0 | J12: =SUM(G12:I12) -> 0 | L12: Số người ăn | M12: =COUNTA(D2:D16) -> 0
